Workbook

Sheet Participants
A1: 🏹 1ST GREENPARK ARCHERY TOURNAMENT — PARTICIPANT REGISTRY
A2: June 12, 2026 | Pasig Greenpark Village Clubhouse, 137 Sydney, Pasig, Metro Manila
A3: # | B3: Archer's Full Name | C3: Age | D3: Category | E3: Bow | F3: Club / Barangay | G3: Target | H3: Contact | I3: Equipment | J3: Payment | K3: Ref # | L3: Amount | M3: Remarks
A4: 1 | B4: Joseph Nesortado Naoe | D4: Open 30-Meter | E4: Barebow | F4: DMZ
A5: 2 | B5: Jebbrich Tan Lim | D5: Open 30-Meter | E5: Barebow | F5: Attack Arena
A6: 3 | B6: Zhean Benito | D6: Open 30-Meter | E6: Olympic Recurve | F6: Attack Arena
A7: 4 | B7: Allan Robert Aruego | D7: Open 30-Meter | E7: Olympic Recurve | F7: Attack Arena
A8: 5 | B8: Sheena Marie Monico | D8: Open 30-Meter | E8: Olympic Recurve | F8: Pasig AC
A9: 6 | B9: Stella Mae Magalang | D9: Open 30-Meter | E9: Olympic Recurve | F9: Buting
A10: 7 | B10: Aizen Zainna Quiellan M. Riego | D10: Open 30-Meter | E10: Olympic Recurve | F10: PAC Maybunga
A11: 8 | B11: Leira Maxene Lagrimas | D11: Open 30-Meter | E11: Olympic Recurve | F11: Brgy. Sta Lucia
A12: 9 | B12: Jasmine Eizelle P. Dipad | D12: Open 30-Meter | E12: Olympic Recurve | F12: N/A
A13: 10 | B13: Allan Chew | D13: Open 30-Meter | E13: Olympic Recurve | F13: Attack Arena
A14: 11 | B14: Myckhielle Joji Tan | D14: Open 30-Meter | E14: Olympic Recurve | F14: Attack Arena
A15: 12 | B15: Sheena Marie Monico | D15: Beginner Advance 15-Meter | E15: Olympic Recurve | F15: Pasig AC
... A22: 19 | B22: Kyara Lorielle Zate | D22: Novice 15-Meter | E22: Olympic Recurve | F22: Pasig Greenpark AC

Sheet Settings
A1: ⚙️ TOURNAMENT SETTINGS & REFERENCE
A2: Reference only. Format is set per-category in each Team Assembly sheet.
A3: Term | B3: Explanation
A4: Dynamic Participants | B4: Add new archer in Scoring sheet (blank row, col B). They auto-appear in Team dropdowns. Scores, Ranks, Seeds, Brackets, Scoresheets all update instantly.
A5: Custom Team Name | B5: For Double or Team format: type your custom team name in Col B of Team Assembly. The formula pre-fills as 'Entry N' — just overwrite with your team name. Bracket shows this custom name.
A6: Rank in Bracket | B6: Seed badge (#N) shown in the first narrow column of each match slot. Entry name shows in the wide column beside it. Both auto-fill from Team Assembly.
A7: Target Assignment | B7: Set the target range (cells D5 'from' and E5 'to') on each Scoring sheet — column E auto-assigns each archer a target number from that range, in order. If the total number of archers fits within the range (e.g. range 3-6, up to 4 archers), everyone gets plain numbers (3,4,5,6). If there are MORE archers than numbers in the range, EVERY archer (including the first batch) gets a letter suffix that cycles A,B,C,... per pass through the range (3A,4A,5A,6A, then 3B,4B,5B,6B, ...) so the format stays consistent across the whole sheet. Auto-propagates to Scoresheet (viewer tab).
A8: Bracket Target Assignment | B8: Each Bracket sheet has its own target range input (top-left of row 2, 'Use Target #s from/to', default 3-6). Every player has their own target cell directly below their seed badge (#) in the bracket. EACH ROUND (R16, QF, SF, Final/3rd) is INDEPENDENT — the range always restarts from the beginning for each round. Within a round, the rule is: if the range size R >= the number of matches in that round, each match gets a UNIQUE target number (no letter suffix), with top player shown as '<num> L' (Left) and bottom as '<num> R' (Right). If R < number of matches, matches cycle through the range with letter suffixes: A = Left (top player), B = Right (bottom player). Letters ALWAYS reset to A/B for each round — they never continue as C/D from a previous round. Example with range 1-8 (R=8): R16 (8 matches, R=8 → unique: 1L/1R, 2L/2R...8L/8R), QF (4 matches, R=8≥4 → unique restarts: 1L/1R, 2L/2R, 3L/3R, 4L/4R), SF (2 matches, R=8≥2 → unique restarts: 1L/1R, 2L/2R), Final+3rd (1+1 match → 1L/1R and 2L/2R). All target cells are pre-filled with a formula but can be typed over to set a different target manually, same as the Scoring sheet's Target column. For QF/SF/Final/3rd-place matches, the target cells stay blank until both competitors in that match are determined (not TBD/BYE).
A9: Club / Barangay | B9: Entered in Scoring sheet col D. Auto-carried to Team Assembly, Bracket, and Scoresheet.
A10: Scoresheet (viewer) | B10: Live-linked to Scoring tab. Print after scores are final and hand to participants. Shows rank, all arrow scores, end totals, and final rank.
A11: Olympic Card | B11: Live-linked to Bracket tab. Print before/after each round for match officials. Shows set scores, set points, and match status per competitor.
A12: Shoot-off | B12: Enter 1-arrow score in orange Shoot-Off column of Scoring sheet. FINAL RANK and Seed update automatically. Higher score = closer to X = better rank.
A13: Seeding | B13: 1v16, 8v9, 5v12, 4v13, 3v14, 6v11, 7v10, 2v15 (WA standard R16 draw).
A14: BYE Rule (WA §10) | B14: Mark BYE=Yes in Team Assembly col L. Bracket shows 🟡 BYE. Opponent auto-advances.

Sheet Open 30M - Scoring
A1: 🏹 OPEN 30-METER — QUALIFICATION SCORING (36 Arrows)
A2: Date: June 12, 2026 | Distance: 30m | WA Rules §9.4 | 0–10 or X
A3: INSTRUCTIONS: Enter 0–10 or X in yellow cells. Add archers in next empty row — formulas auto-extend. Shoot-off (orange col): fill ONLY for tied archers. FINAL RANK = official bracket seed.
A4: # | B4: Archer's Full Name | C4: Bow | D4: Club / Barangay | E4: Target | F4: End 1 (6 arrows) | L4: End 2 (6 arrows) | R4: End 3 (6 arrows) | X4: End 4 (6 arrows) | AD4: End 5 (6 arrows) | AJ4: End 6 (6 arrows) | AP4: END SUBTOTALS | AV4: RESULTS SUMMARY
A5: Use Target #s → (from / to) | D5: 3 | E5: 6 | F5: A1 | G5: A2 | H5: A3 | I5: A4 | J5: A5 | K5: A6 | L5: A7 | M5: A8 | N5: A9 | O5: A10 | P5: A11 | Q5: A12 | R5: A13 | S5: A14 | T5: A15 | U5: A16 | V5: A17 | W5: A18 | X5: A19 | Y5: A20 | Z5: A21 | AA5: A22 | AB5: A23 | AC5: A24 | AD5: A25 | AE5: A26 | AF5: A27 | AG5: A28 | AH5: A29 | AI5: A30 | AJ5: A31 | AK5: A32 | AL5: A33 | AM5: A34 | AN5: A35 | AO5: A36 | AP5: E1 | AQ5: E2 | AR5: E3 | AS5: E4 | AT5: E5 | AU5: E6 | AV5: TOTAL | AW5: X | AX5: 10s | AY5: 9s | AZ5: RANK* (prelim) | BA5: SHOOT-OFF (1 arrow) | BB5: FINAL RANK
A6: =IF(B6<>"",COUNTA($B$6:B6),"") -> 1 | B6: Joseph Nesortado Naoe | C6: Barebow | D6: DMZ | E6: =IF(B6="","",IF(COUNTA($B$6:$B$69)<=(E5-D5+1),(D5+MOD(A6-1,(E5-D5+1))),(D5+MOD(A6-1,(E5-D5+1)))&CHAR(65+FLOOR((A6-1)/(E5-D5+1),1)))) -> 3A | AP6: =IF(B6<>"",IF(F6="X",10,IF(F6="M",0,IF(ISNUMBER(F6),F6,0)))+IF(G6="X",10,IF(G6="M",0,IF(ISNUMBER(G6),G6,0)))+IF(H6="X",10,IF(H6="M",0,IF(ISNUMBER(H6),H6,0)))+IF(I6="X",10,IF(I6="M",0,IF(ISNUMBER(I6),I6,0)))+IF(J6="X",10,IF(J6="M",0,IF(ISNUMBER(J6),J6,0)))+IF(K6="X",10,IF(K6="M",0,IF(ISNUMBER(K6),K6,0))),"") -> 0 | AQ6: =IF(B6<>"",IF(L6="X",10,IF(L6="M",0,IF(ISNUMBER(L6),L6,0)))+IF(M6="X",10,IF(M6="M",0,IF(ISNUMBER(M6),M6,0)))+IF(N6="X",10,IF(N6="M",0,IF(ISNUMBER(N6),N6,0)))+IF(O6="X",10,IF(O6="M",0,IF(ISNUMBER(O6),O6,0)))+IF(P6="X",10,IF(P6="M",0,IF(ISNUMBER(P6),P6,0)))+IF(Q6="X",10,IF(Q6="M",0,IF(ISNUMBER(Q6),Q6,0))),"") -> 0 | AR6: =IF(B6<>"",IF(R6="X",10,IF(R6="M",0,IF(ISNUMBER(R6),R6,0)))+IF(S6="X",10,IF(S6="M",0,IF(ISNUMBER(S6),S6,0)))+IF(T6="X",10,IF(T6="M",0,IF(ISNUMBER(T6),T6,0)))+IF(U6="X",10,IF(U6="M",0,IF(ISNUMBER(U6),U6,0)))+IF(V6="X",10,IF(V6="M",0,IF(ISNUMBER(V6),V6,0)))+IF(W6="X",10,IF(W6="M",0,IF(ISNUMBER(W6),W6,0))),"") -> 0 | AS6: =IF(B6<>"",IF(X6="X",10,IF(X6="M",0,IF(ISNUMBER(X6),X6,0)))+IF(Y6="X",10,IF(Y6="M",0,IF(ISNUMBER(Y6),Y6,0)))+IF(Z6="X",10,IF(Z6="M",0,IF(ISNUMBER(Z6),Z6,0)))+IF(AA6="X",10,IF(AA6="M",0,IF(ISNUMBER(AA6),AA6,0)))+IF(AB6="X",10,IF(AB6="M",0,IF(ISNUMBER(AB6),AB6,0)))+IF(AC6="X",10,IF(AC6="M",0,IF(ISNUMBER(AC6),AC6,0))),"") -> 0 | AT6: =IF(B6<>"",IF(AD6="X",10,IF(AD6="M",0,IF(ISNUMBER(AD6),AD6,0)))+IF(AE6="X",10,IF(AE6="M",0,IF(ISNUMBER(AE6),AE6,0)))+IF(AF6="X",10,IF(AF6="M",0,IF(ISNUMBER(AF6),AF6,0)))+IF(AG6="X",10,IF(AG6="M",0,IF(ISNUMBER(AG6),AG6,0)))+IF(AH6="X",10,IF(AH6="M",0,IF(ISNUMBER(AH6),AH6,0)))+IF(AI6="X",10,IF(AI6="M",0,IF(ISNUMBER(AI6),AI6,0))),"") -> 0 | AU6: =IF(B6<>"",IF(AJ6="X",10,IF(AJ6="M",0,IF(ISNUMBER(AJ6),AJ6,0)))+IF(AK6="X",10,IF(AK6="M",0,IF(ISNUMBER(AK6),AK6,0)))+IF(AL6="X",10,IF(AL6="M",0,IF(ISNUMBER(AL6),AL6,0)))+IF(AM6="X",10,IF(AM6="M",0,IF(ISNUMBER(AM6),AM6,0)))+IF(AN6="X",10,IF(AN6="M",0,IF(ISNUMBER(AN6),AN6,0)))+IF(AO6="X",10,IF(AO6="M",0,IF(ISNUMBER(AO6),AO6,0))),"") -> 0 | AV6: =IF(B6<>"",AP6+AQ6+AR6+AS6+AT6+AU6,"") -> 0 | AW6: =IF(B6<>"",IF(F6="X",1,0)+IF(G6="X",1,0)+IF(H6="X",1,0)+IF(I6="X",1,0)+IF(J6="X",1,0)+IF(K6="X",1,0)+IF(L6="X",1,0)+IF(M6="X",1,0)+IF(N6="X",1,0)+IF(O6="X",1,0)+IF(P6="X",1,0)+IF(Q6="X",1,0)+IF(R6="X",1,0)+IF(S6="X",1,0)+IF(T6="X",1,0)+IF(U6="X",1,0)+IF(V6="X",1,0)+IF(W6="X",1,0)+IF(X6="X",1,0)+IF(Y6="X",1,0)+IF(Z6="X",1,0)+IF(AA6="X",1,0)+IF(AB6="X",1,0)+IF(AC6="X",1,0)+IF(AD6="X",1,0)+IF(AE6="X",1,0)+IF(AF6="X",1,0)+IF(AG6="X",1,0)+IF(AH6="X",1,0)+IF(AI6="X",1,0)+IF(AJ6="X",1,0)+IF(AK6="X",1,0)+IF(AL6="X",1,0)+IF(AM6="X",1,0)+IF(AN6="X",1,0)+IF(AO6="X",1,0),"") -> 0 | AX6: =IF(B6<>"",IF(OR(F6="X",F6=10),1,0)+IF(OR(G6="X",G6=10),1,0)+IF(OR(H6="X",H6=10),1,0)+IF(OR(I6="X",I6=10),1,0)+IF(OR(J6="X",J6=10),1,0)+IF(OR(K6="X",K6=10),1,0)+IF(OR(L6="X",L6=10),1,0)+IF(OR(M6="X",M6=10),1,0)+IF(OR(N6="X",N6=10),1,0)+IF(OR(O6="X",O6=10),1,0)+IF(OR(P6="X",P6=10),1,0)+IF(OR(Q6="X",Q6=10),1,0)+IF(OR(R6="X",R6=10),1,0)+IF(OR(S6="X",S6=10),1,0)+IF(OR(T6="X",T6=10),1,0)+IF(OR(U6="X",U6=10),1,0)+IF(OR(V6="X",V6=10),1,0)+IF(OR(W6="X",W6=10),1,0)+IF(OR(X6="X",X6=10),1,0)+IF(OR(Y6="X",Y6=10),1,0)+IF(OR(Z6="X",Z6=10),1,0)+IF(OR(AA6="X",AA6=10),1,0)+IF(OR(AB6="X",AB6=10),1,0)+IF(OR(AC6="X",AC6=10),1,0)+IF(OR(AD6="X",AD6=10),1,0)+IF(OR(AE6="X",AE6=10),1,0)+IF(OR(AF6="X",AF6=10),1,0)+IF(OR(AG6="X",AG6=10),1,0)+IF(OR(AH6="X",AH6=10),1,0)+IF(OR(AI6="X",AI6=10),1,0)+IF(OR(AJ6="X",AJ6=10),1,0)+IF(OR(AK6="X",AK6=10),1,0)+IF(OR(AL6="X",AL6=10),1,0)+IF(OR(AM6="X",AM6=10),1,0)+IF(OR(AN6="X",AN6=10),1,0)+IF(OR(AO6="X",AO6=10),1,0),"") -> 0 | AY6: =IF(B6<>"",IF(F6=9,1,0)+IF(G6=9,1,0)+IF(H6=9,1,0)+IF(I6=9,1,0)+IF(J6=9,1,0)+IF(K6=9,1,0)+IF(L6=9,1,0)+IF(M6=9,1,0)+IF(N6=9,1,0)+IF(O6=9,1,0)+IF(P6=9,1,0)+IF(Q6=9,1,0)+IF(R6=9,1,0)+IF(S6=9,1,0)+IF(T6=9,1,0)+IF(U6=9,1,0)+IF(V6=9,1,0)+IF(W6=9,1,0)+IF(X6=9,1,0)+IF(Y6=9,1,0)+IF(Z6=9,1,0)+IF(AA6=9,1,0)+IF(AB6=9,1,0)+IF(AC6=9,1,0)+IF(AD6=9,1,0)+IF(AE6=9,1,0)+IF(AF6=9,1,0)+IF(AG6=9,1,0)+IF(AH6=9,1,0)+IF(AI6=9,1,0)+IF(AJ6=9,1,0)+IF(AK6=9,1,0)+IF(AL6=9,1,0)+IF(AM6=9,1,0)+IF(AN6=9,1,0)+IF(AO6=9,1,0),"") -> 0 | AZ6: =IF(B6<>"",SUMPRODUCT(($AV$6:$AV$1000>AV6)*ISNUMBER($AV$6:$AV$1000))+1+SUMPRODUCT(($AV$6:$AV$1000=AV6)*($AW$6:$AW$1000>AW6)*ISNUMBER($AV$6:$AV$1000)*ISNUMBER($AW$6:$AW$1000))+SUMPRODUCT(($AV$6:$AV$1000=AV6)*($AW$6:$AW$1000=AW6)*($AX$6:$AX$1000>AX6)*ISNUMBER($AV$6:$AV$1000)*ISNUMBER($AX$6:$AX$1000))+SUMPRODUCT(($AV$6:$AV$1000=AV6)*($AW$6:$AW$1000=AW6)*($AX$6:$AX$1000=AX6)*($AY$6:$AY$1000>AY6)*ISNUMBER($AV$6:$AV$1000)*ISNUMBER($AY$6:$AY$1000)),"") -> 1 | BB6: =IF(B6<>"",SUMPRODUCT(($AV$6:$AV$1000>AV6)*ISNUMBER($AV$6:$AV$1000))+1+SUMPRODUCT(($AV$6:$AV$1000=AV6)*($AW$6:$AW$1000>AW6)*ISNUMBER($AV$6:$AV$1000)*ISNUMBER($AW$6:$AW$1000))+SUMPRODUCT(($AV$6:$AV$1000=AV6)*($AW$6:$AW$1000=AW6)*($AX$6:$AX$1000>AX6)*ISNUMBER($AV$6:$AV$1000)*ISNUMBER($AX$6:$AX$1000))+SUMPRODUCT(($AV$6:$AV$1000=AV6)*($AW$6:$AW$1000=AW6)*($AX$6:$AX$1000=AX6)*($AY$6:$AY$1000>AY6)*ISNUMBER($AV$6:$AV$1000)*ISNUMBER($AY$6:$AY$1000))+SUMPRODUCT(($AV$6:$AV$1000=AV6)*($AW$6:$AW$1000=AW6)*($AX$6:$AX$1000=AX6)*($AY$6:$AY$1000=AY6)*($BA$6:$BA$1000>BA6)*ISNUMBER($AV$6:$AV$1000)*ISNUMBER($BA$6:$BA$1000)),"") -> 1
A7: =IF(B7<>"",COUNTA($B$6:B7),"") -> 2 | B7: Jebbrich Tan Lim | C7: Barebow | D7: Attack Arena | E7: =IF(B7="","",IF(COUNTA($B$6:$B$69)<=(E5-D5+1),(D5+MOD(A7-1,(E5-D5+1))),(D5+MOD(A7-1,(E5-D5+1)))&CHAR(65+FLOOR((A7-1)/(E5-D5+1),1)))) -> 4A | AP7: =IF(B7<>"",IF(F7="X",10,IF(F7="M",0,IF(ISNUMBER(F7),F7,0)))+IF(G7="X",10,IF(G7="M",0,IF(ISNUMBER(G7),G7,0)))+IF(H7="X",10,IF(H7="M",0,IF(ISNUMBER(H7),H7,0)))+IF(I7="X",10,IF(I7="M",0,IF(ISNUMBER(I7),I7,0)))+IF(J7="X",10,IF(J7="M",0,IF(ISNUMBER(J7),J7,0)))+IF(K7="X",10,IF(K7="M",0,IF(ISNUMBER(K7),K7,0))),"") -> 0 | AQ7: =IF(B7<>"",IF(L7="X",10,IF(L7="M",0,IF(ISNUMBER(L7),L7,0)))+IF(M7="X",10,IF(M7="M",0,IF(ISNUMBER(M7),M7,0)))+IF(N7="X",10,IF(N7="M",0,IF(ISNUMBER(N7),N7,0)))+IF(O7="X",10,IF(O7="M",0,IF(ISNUMBER(O7),O7,0)))+IF(P7="X",10,IF(P7="M",0,IF(ISNUMBER(P7),P7,0)))+IF(Q7="X",10,IF(Q7="M",0,IF(ISNUMBER(Q7),Q7,0))),"") -> 0 | AR7: =IF(B7<>"",IF(R7="X",10,IF(R7="M",0,IF(ISNUMBER(R7),R7,0)))+IF(S7="X",10,IF(S7="M",0,IF(ISNUMBER(S7),S7,0)))+IF(T7="X",10,IF(T7="M",0,IF(ISNUMBER(T7),T7,0)))+IF(U7="X",10,IF(U7="M",0,IF(ISNUMBER(U7),U7,0)))+IF(V7="X",10,IF(V7="M",0,IF(ISNUMBER(V7),V7,0)))+IF(W7="X",10,IF(W7="M",0,IF(ISNUMBER(W7),W7,0))),"") -> 0 | AS7: =IF(B7<>"",IF(X7="X",10,IF(X7="M",0,IF(ISNUMBER(X7),X7,0)))+IF(Y7="X",10,IF(Y7="M",0,IF(ISNUMBER(Y7),Y7,0)))+IF(Z7="X",10,IF(Z7="M",0,IF(ISNUMBER(Z7),Z7,0)))+IF(AA7="X",10,IF(AA7="M",0,IF(ISNUMBER(AA7),AA7,0)))+IF(AB7="X",10,IF(AB7="M",0,IF(ISNUMBER(AB7),AB7,0)))+IF(AC7="X",10,IF(AC7="M",0,IF(ISNUMBER(AC7),AC7,0))),"") -> 0 | AT7: =IF(B7<>"",IF(AD7="X",10,IF(AD7="M",0,IF(ISNUMBER(AD7),AD7,0)))+IF(AE7="X",10,IF(AE7="M",0,IF(ISNUMBER(AE7),AE7,0)))+IF(AF7="X",10,IF(AF7="M",0,IF(ISNUMBER(AF7),AF7,0)))+IF(AG7="X",10,IF(AG7="M",0,IF(ISNUMBER(AG7),AG7,0)))+IF(AH7="X",10,IF(AH7="M",0,IF(ISNUMBER(AH7),AH7,0)))+IF(AI7="X",10,IF(AI7="M",0,IF(ISNUMBER(AI7),AI7,0))),"") -> 0 | AU7: =IF(B7<>"",IF(AJ7="X",10,IF(AJ7="M",0,IF(ISNUMBER(AJ7),AJ7,0)))+IF(AK7="X",10,IF(AK7="M",0,IF(ISNUMBER(AK7),AK7,0)))+IF(AL7="X",10,IF(AL7="M",0,IF(ISNUMBER(AL7),AL7,0)))+IF(AM7="X",10,IF(AM7="M",0,IF(ISNUMBER(AM7),AM7,0)))+IF(AN7="X",10,IF(AN7="M",0,IF(ISNUMBER(AN7),AN7,0)))+IF(AO7="X",10,IF(AO7="M",0,IF(ISNUMBER(AO7),AO7,0))),"") -> 0 | AV7: =IF(B7<>"",AP7+AQ7+AR7+AS7+AT7+AU7,"") -> 0 | AW7: =IF(B7<>"",IF(F7="X",1,0)+IF(G7="X",1,0)+IF(H7="X",1,0)+IF(I7="X",1,0)+IF(J7="X",1,0)+IF(K7="X",1,0)+IF(L7="X",1,0)+IF(M7="X",1,0)+IF(N7="X",1,0)+IF(O7="X",1,0)+IF(P7="X",1,0)+IF(Q7="X",1,0)+IF(R7="X",1,0)+IF(S7="X",1,0)+IF(T7="X",1,0)+IF(U7="X",1,0)+IF(V7="X",1,0)+IF(W7="X",1,0)+IF(X7="X",1,0)+IF(Y7="X",1,0)+IF(Z7="X",1,0)+IF(AA7="X",1,0)+IF(AB7="X",1,0)+IF(AC7="X",1,0)+IF(AD7="X",1,0)+IF(AE7="X",1,0)+IF(AF7="X",1,0)+IF(AG7="X",1,0)+IF(AH7="X",1,0)+IF(AI7="X",1,0)+IF(AJ7="X",1,0)+IF(AK7="X",1,0)+IF(AL7="X",1,0)+IF(AM7="X",1,0)+IF(AN7="X",1,0)+IF(AO7="X",1,0),"") -> 0 | AX7: =IF(B7<>"",IF(OR(F7="X",F7=10),1,0)+IF(OR(G7="X",G7=10),1,0)+IF(OR(H7="X",H7=10),1,0)+IF(OR(I7="X",I7=10),1,0)+IF(OR(J7="X",J7=10),1,0)+IF(OR(K7="X",K7=10),1,0)+IF(OR(L7="X",L7=10),1,0)+IF(OR(M7="X",M7=10),1,0)+IF(OR(N7="X",N7=10),1,0)+IF(OR(O7="X",O7=10),1,0)+IF(OR(P7="X",P7=10),1,0)+IF(OR(Q7="X",Q7=10),1,0)+IF(OR(R7="X",R7=10),1,0)+IF(OR(S7="X",S7=10),1,0)+IF(OR(T7="X",T7=10),1,0)+IF(OR(U7="X",U7=10),1,0)+IF(OR(V7="X",V7=10),1,0)+IF(OR(W7="X",W7=10),1,0)+IF(OR(X7="X",X7=10),1,0)+IF(OR(Y7="X",Y7=10),1,0)+IF(OR(Z7="X",Z7=10),1,0)+IF(OR(AA7="X",AA7=10),1,0)+IF(OR(AB7="X",AB7=10),1,0)+IF(OR(AC7="X",AC7=10),1,0)+IF(OR(AD7="X",AD7=10),1,0)+IF(OR(AE7="X",AE7=10),1,0)+IF(OR(AF7="X",AF7=10),1,0)+IF(OR(AG7="X",AG7=10),1,0)+IF(OR(AH7="X",AH7=10),1,0)+IF(OR(AI7="X",AI7=10),1,0)+IF(OR(AJ7="X",AJ7=10),1,0)+IF(OR(AK7="X",AK7=10),1,0)+IF(OR(AL7="X",AL7=10),1,0)+IF(OR(AM7="X",AM7=10),1,0)+IF(OR(AN7="X",AN7=10),1,0)+IF(OR(AO7="X",AO7=10),1,0),"") -> 0 | AY7: =IF(B7<>"",IF(F7=9,1,0)+IF(G7=9,1,0)+IF(H7=9,1,0)+IF(I7=9,1,0)+IF(J7=9,1,0)+IF(K7=9,1,0)+IF(L7=9,1,0)+IF(M7=9,1,0)+IF(N7=9,1,0)+IF(O7=9,1,0)+IF(P7=9,1,0)+IF(Q7=9,1,0)+IF(R7=9,1,0)+IF(S7=9,1,0)+IF(T7=9,1,0)+IF(U7=9,1,0)+IF(V7=9,1,0)+IF(W7=9,1,0)+IF(X7=9,1,0)+IF(Y7=9,1,0)+IF(Z7=9,1,0)+IF(AA7=9,1,0)+IF(AB7=9,1,0)+IF(AC7=9,1,0)+IF(AD7=9,1,0)+IF(AE7=9,1,0)+IF(AF7=9,1,0)+IF(AG7=9,1,0)+IF(AH7=9,1,0)+IF(AI7=9,1,0)+IF(AJ7=9,1,0)+IF(AK7=9,1,0)+IF(AL7=9,1,0)+IF(AM7=9,1,0)+IF(AN7=9,1,0)+IF(AO7=9,1,0),"") -> 0 | AZ7: =IF(B7<>"",SUMPRODUCT(($AV$6:$AV$1000>AV7)*ISNUMBER($AV$6:$AV$1000))+1+SUMPRODUCT(($AV$6:$AV$1000=AV7)*($AW$6:$AW$1000>AW7)*ISNUMBER($AV$6:$AV$1000)*ISNUMBER($AW$6:$AW$1000))+SUMPRODUCT(($AV$6:$AV$1000=AV7)*($AW$6:$AW$1000=AW7)*($AX$6:$AX$1000>AX7)*ISNUMBER($AV$6:$AV$1000)*ISNUMBER($AX$6:$AX$1000))+SUMPRODUCT(($AV$6:$AV$1000=AV7)*($AW$6:$AW$1000=AW7)*($AX$6:$AX$1000=AX7)*($AY$6:$AY$1000>AY7)*ISNUMBER($AV$6:$AV$1000)*ISNUMBER($AY$6:$AY$1000)),"") -> 1 | BB7: =IF(B7<>"",SUMPRODUCT(($AV$6:$AV$1000>AV7)*ISNUMBER($AV$6:$AV$1000))+1+SUMPRODUCT(($AV$6:$AV$1000=AV7)*($AW$6:$AW$1000>AW7)*ISNUMBER($AV$6:$AV$1000)*ISNUMBER($AW$6:$AW$1000))+SUMPRODUCT(($AV$6:$AV$1000=AV7)*($AW$6:$AW$1000=AW7)*($AX$6:$AX$1000>AX7)*ISNUMBER($AV$6:$AV$1000)*ISNUMBER($AX$6:$AX$1000))+SUMPRODUCT(($AV$6:$AV$1000=AV7)*($AW$6:$AW$1000=AW7)*($AX$6:$AX$1000=AX7)*($AY$6:$AY$1000>AY7)*ISNUMBER($AV$6:$AV$1000)*ISNUMBER($AY$6:$AY$1000))+SUMPRODUCT(($AV$6:$AV$1000=AV7)*($AW$6:$AW$1000=AW7)*($AX$6:$AX$1000=AX7)*($AY$6:$AY$1000=AY7)*($BA$6:$BA$1000>BA7)*ISNUMBER($AV$6:$AV$1000)*ISNUMBER($BA$6:$BA$1000)),"") -> 1
A8: =IF(B8<>"",COUNTA($B$6:B8),"") -> 3 | B8: Zhean Benito | C8: Olympic Recurve | D8: Attack Arena | E8: =IF(B8="","",IF(COUNTA($B$6:$B$69)<=(E5-D5+1),(D5+MOD(A8-1,(E5-D5+1))),(D5+MOD(A8-1,(E5-D5+1)))&CHAR(65+FLOOR((A8-1)/(E5-D5+1),1)))) -> 5A | AP8: =IF(B8<>"",IF(F8="X",10,IF(F8="M",0,IF(ISNUMBER(F8),F8,0)))+IF(G8="X",10,IF(G8="M",0,IF(ISNUMBER(G8),G8,0)))+IF(H8="X",10,IF(H8="M",0,IF(ISNUMBER(H8),H8,0)))+IF(I8="X",10,IF(I8="M",0,IF(ISNUMBER(I8),I8,0)))+IF(J8="X",10,IF(J8="M",0,IF(ISNUMBER(J8),J8,0)))+IF(K8="X",10,IF(K8="M",0,IF(ISNUMBER(K8),K8,0))),"") -> 0 | AQ8: =IF(B8<>"",IF(L8="X",10,IF(L8="M",0,IF(ISNUMBER(L8),L8,0)))+IF(M8="X",10,IF(M8="M",0,IF(ISNUMBER(M8),M8,0)))+IF(N8="X",10,IF(N8="M",0,IF(ISNUMBER(N8),N8,0)))+IF(O8="X",10,IF(O8="M",0,IF(ISNUMBER(O8),O8,0)))+IF(P8="X",10,IF(P8="M",0,IF(ISNUMBER(P8),P8,0)))+IF(Q8="X",10,IF(Q8="M",0,IF(ISNUMBER(Q8),Q8,0))),"") -> 0 | AR8: =IF(B8<>"",IF(R8="X",10,IF(R8="M",0,IF(ISNUMBER(R8),R8,0)))+IF(S8="X",10,IF(S8="M",0,IF(ISNUMBER(S8),S8,0)))+IF(T8="X",10,IF(T8="M",0,IF(ISNUMBER(T8),T8,0)))+IF(U8="X",10,IF(U8="M",0,IF(ISNUMBER(U8),U8,0)))+IF(V8="X",10,IF(V8="M",0,IF(ISNUMBER(V8),V8,0)))+IF(W8="X",10,IF(W8="M",0,IF(ISNUMBER(W8),W8,0))),"") -> 0 | AS8: =IF(B8<>"",IF(X8="X",10,IF(X8="M",0,IF(ISNUMBER(X8),X8,0)))+IF(Y8="X",10,IF(Y8="M",0,IF(ISNUMBER(Y8),Y8,0)))+IF(Z8="X",10,IF(Z8="M",0,IF(ISNUMBER(Z8),Z8,0)))+IF(AA8="X",10,IF(AA8="M",0,IF(ISNUMBER(AA8),AA8,0)))+IF(AB8="X",10,IF(AB8="M",0,IF(ISNUMBER(AB8),AB8,0)))+IF(AC8="X",10,IF(AC8="M",0,IF(ISNUMBER(AC8),AC8,0))),"") -> 0 | AT8: =IF(B8<>"",IF(AD8="X",10,IF(AD8="M",0,IF(ISNUMBER(AD8),AD8,0)))+IF(AE8="X",10,IF(AE8="M",0,IF(ISNUMBER(AE8),AE8,0)))+IF(AF8="X",10,IF(AF8="M",0,IF(ISNUMBER(AF8),AF8,0)))+IF(AG8="X",10,IF(AG8="M",0,IF(ISNUMBER(AG8),AG8,0)))+IF(AH8="X",10,IF(AH8="M",0,IF(ISNUMBER(AH8),AH8,0)))+IF(AI8="X",10,IF(AI8="M",0,IF(ISNUMBER(AI8),AI8,0))),"") -> 0 | AU8: =IF(B8<>"",IF(AJ8="X",10,IF(AJ8="M",0,IF(ISNUMBER(AJ8),AJ8,0)))+IF(AK8="X",10,IF(AK8="M",0,IF(ISNUMBER(AK8),AK8,0)))+IF(AL8="X",10,IF(AL8="M",0,IF(ISNUMBER(AL8),AL8,0)))+IF(AM8="X",10,IF(AM8="M",0,IF(ISNUMBER(AM8),AM8,0)))+IF(AN8="X",10,IF(AN8="M",0,IF(ISNUMBER(AN8),AN8,0)))+IF(AO8="X",10,IF(AO8="M",0,IF(ISNUMBER(AO8),AO8,0))),"") -> 0 | AV8: =IF(B8<>"",AP8+AQ8+AR8+AS8+AT8+AU8,"") -> 0 | AW8: =IF(B8<>"",IF(F8="X",1,0)+IF(G8="X",1,0)+IF(H8="X",1,0)+IF(I8="X",1,0)+IF(J8="X",1,0)+IF(K8="X",1,0)+IF(L8="X",1,0)+IF(M8="X",1,0)+IF(N8="X",1,0)+IF(O8="X",1,0)+IF(P8="X",1,0)+IF(Q8="X",1,0)+IF(R8="X",1,0)+IF(S8="X",1,0)+IF(T8="X",1,0)+IF(U8="X",1,0)+IF(V8="X",1,0)+IF(W8="X",1,0)+IF(X8="X",1,0)+IF(Y8="X",1,0)+IF(Z8="X",1,0)+IF(AA8="X",1,0)+IF(AB8="X",1,0)+IF(AC8="X",1,0)+IF(AD8="X",1,0)+IF(AE8="X",1,0)+IF(AF8="X",1,0)+IF(AG8="X",1,0)+IF(AH8="X",1,0)+IF(AI8="X",1,0)+IF(AJ8="X",1,0)+IF(AK8="X",1,0)+IF(AL8="X",1,0)+IF(AM8="X",1,0)+IF(AN8="X",1,0)+IF(AO8="X",1,0),"") -> 0 | AX8: =IF(B8<>"",IF(OR(F8="X",F8=10),1,0)+IF(OR(G8="X",G8=10),1,0)+IF(OR(H8="X",H8=10),1,0)+IF(OR(I8="X",I8=10),1,0)+IF(OR(J8="X",J8=10),1,0)+IF(OR(K8="X",K8=10),1,0)+IF(OR(L8="X",L8=10),1,0)+IF(OR(M8="X",M8=10),1,0)+IF(OR(N8="X",N8=10),1,0)+IF(OR(O8="X",O8=10),1,0)+IF(OR(P8="X",P8=10),1,0)+IF(OR(Q8="X",Q8=10),1,0)+IF(OR(R8="X",R8=10),1,0)+IF(OR(S8="X",S8=10),1,0)+IF(OR(T8="X",T8=10),1,0)+IF(OR(U8="X",U8=10),1,0)+IF(OR(V8="X",V8=10),1,0)+IF(OR(W8="X",W8=10),1,0)+IF(OR(X8="X",X8=10),1,0)+IF(OR(Y8="X",Y8=10),1,0)+IF(OR(Z8="X",Z8=10),1,0)+IF(OR(AA8="X",AA8=10),1,0)+IF(OR(AB8="X",AB8=10),1,0)+IF(OR(AC8="X",AC8=10),1,0)+IF(OR(AD8="X",AD8=10),1,0)+IF(OR(AE8="X",AE8=10),1,0)+IF(OR(AF8="X",AF8=10),1,0)+IF(OR(AG8="X",AG8=10),1,0)+IF(OR(AH8="X",AH8=10),1,0)+IF(OR(AI8="X",AI8=10),1,0)+IF(OR(AJ8="X",AJ8=10),1,0)+IF(OR(AK8="X",AK8=10),1,0)+IF(OR(AL8="X",AL8=10),1,0)+IF(OR(AM8="X",AM8=10),1,0)+IF(OR(AN8="X",AN8=10),1,0)+IF(OR(AO8="X",AO8=10),1,0),"") -> 0 | AY8: =IF(B8<>"",IF(F8=9,1,0)+IF(G8=9,1,0)+IF(H8=9,1,0)+IF(I8=9,1,0)+IF(J8=9,1,0)+IF(K8=9,1,0)+IF(L8=9,1,0)+IF(M8=9,1,0)+IF(N8=9,1,0)+IF(O8=9,1,0)+IF(P8=9,1,0)+IF(Q8=9,1,0)+IF(R8=9,1,0)+IF(S8=9,1,0)+IF(T8=9,1,0)+IF(U8=9,1,0)+IF(V8=9,1,0)+IF(W8=9,1,0)+IF(X8=9,1,0)+IF(Y8=9,1,0)+IF(Z8=9,1,0)+IF(AA8=9,1,0)+IF(AB8=9,1,0)+IF(AC8=9,1,0)+IF(AD8=9,1,0)+IF(AE8=9,1,0)+IF(AF8=9,1,0)+IF(AG8=9,1,0)+IF(AH8=9,1,0)+IF(AI8=9,1,0)+IF(AJ8=9,1,0)+IF(AK8=9,1,0)+IF(AL8=9,1,0)+IF(AM8=9,1,0)+IF(AN8=9,1,0)+IF(AO8=9,1,0),"") -> 0 | AZ8: =IF(B8<>"",SUMPRODUCT(($AV$6:$AV$1000>AV8)*ISNUMBER($AV$6:$AV$1000))+1+SUMPRODUCT(($AV$6:$AV$1000=AV8)*($AW$6:$AW$1000>AW8)*ISNUMBER($AV$6:$AV$1000)*ISNUMBER($AW$6:$AW$1000))+SUMPRODUCT(($AV$6:$AV$1000=AV8)*($AW$6:$AW$1000=AW8)*($AX$6:$AX$1000>AX8)*ISNUMBER($AV$6:$AV$1000)*ISNUMBER($AX$6:$AX$1000))+SUMPRODUCT(($AV$6:$AV$1000=AV8)*($AW$6:$AW$1000=AW8)*($AX$6:$AX$1000=AX8)*($AY$6:$AY$1000>AY8)*ISNUMBER($AV$6:$AV$1000)*ISNUMBER($AY$6:$AY$1000)),"") -> 1 | BB8: =IF(B8<>"",SUMPRODUCT(($AV$6:$AV$1000>AV8)*ISNUMBER($AV$6:$AV$1000))+1+SUMPRODUCT(($AV$6:$AV$1000=AV8)*($AW$6:$AW$1000>AW8)*ISNUMBER($AV$6:$AV$1000)*ISNUMBER($AW$6:$AW$1000))+SUMPRODUCT(($AV$6:$AV$1000=AV8)*($AW$6:$AW$1000=AW8)*($AX$6:$AX$1000>AX8)*ISNUMBER($AV$6:$AV$1000)*ISNUMBER($AX$6:$AX$1000))+SUMPRODUCT(($AV$6:$AV$1000=AV8)*($AW$6:$AW$1000=AW8)*($AX$6:$AX$1000=AX8)*($AY$6:$AY$1000>AY8)*ISNUMBER($AV$6:$AV$1000)*ISNUMBER($AY$6:$AY$1000))+SUMPRODUCT(($AV$6:$AV$1000=AV8)*($AW$6:$AW$1000=AW8)*($AX$6:$AX$1000=AX8)*($AY$6:$AY$1000=AY8)*($BA$6:$BA$1000>BA8)*ISNUMBER($AV$6:$AV$1000)*ISNUMBER($BA$6:$BA$1000)),"") -> 1
A9: =IF(B9<>"",COUNTA($B$6:B9),"") -> 4 | B9: Allan Robert Aruego | C9: Olympic Recurve | D9: Attack Arena | E9: =IF(B9="","",IF(COUNTA($B$6:$B$69)<=(E5-D5+1),(D5+MOD(A9-1,(E5-D5+1))),(D5+MOD(A9-1,(E5-D5+1)))&CHAR(65+FLOOR((A9-1)/(E5-D5+1),1)))) -> 6A | AP9: =IF(B9<>"",IF(F9="X",10,IF(F9="M",0,IF(ISNUMBER(F9),F9,0)))+IF(G9="X",10,IF(G9="M",0,IF(ISNUMBER(G9),G9,0)))+IF(H9="X",10,IF(H9="M",0,IF(ISNUMBER(H9),H9,0)))+IF(I9="X",10,IF(I9="M",0,IF(ISNUMBER(I9),I9,0)))+IF(J9="X",10,IF(J9="M",0,IF(ISNUMBER(J9),J9,0)))+IF(K9="X",10,IF(K9="M",0,IF(ISNUMBER(K9),K9,0))),"") -> 0 | AQ9: =IF(B9<>"",IF(L9="X",10,IF(L9="M",0,IF(ISNUMBER(L9),L9,0)))+IF(M9="X",10,IF(M9="M",0,IF(ISNUMBER(M9),M9,0)))+IF(N9="X",10,IF(N9="M",0,IF(ISNUMBER(N9),N9,0)))+IF(O9="X",10,IF(O9="M",0,IF(ISNUMBER(O9),O9,0)))+IF(P9="X",10,IF(P9="M",0,IF(ISNUMBER(P9),P9,0)))+IF(Q9="X",10,IF(Q9="M",0,IF(ISNUMBER(Q9),Q9,0))),"") -> 0 | AR9: =IF(B9<>"",IF(R9="X",10,IF(R9="M",0,IF(ISNUMBER(R9),R9,0)))+IF(S9="X",10,IF(S9="M",0,IF(ISNUMBER(S9),S9,0)))+IF(T9="X",10,IF(T9="M",0,IF(ISNUMBER(T9),T9,0)))+IF(U9="X",10,IF(U9="M",0,IF(ISNUMBER(U9),U9,0)))+IF(V9="X",10,IF(V9="M",0,IF(ISNUMBER(V9),V9,0)))+IF(W9="X",10,IF(W9="M",0,IF(ISNUMBER(W9),W9,0))),"") -> 0 | AS9: =IF(B9<>"",IF(X9="X",10,IF(X9="M",0,IF(ISNUMBER(X9),X9,0)))+IF(Y9="X",10,IF(Y9="M",0,IF(ISNUMBER(Y9),Y9,0)))+IF(Z9="X",10,IF(Z9="M",0,IF(ISNUMBER(Z9),Z9,0)))+IF(AA9="X",10,IF(AA9="M",0,IF(ISNUMBER(AA9),AA9,0)))+IF(AB9="X",10,IF(AB9="M",0,IF(ISNUMBER(AB9),AB9,0)))+IF(AC9="X",10,IF(AC9="M",0,IF(ISNUMBER(AC9),AC9,0))),"") -> 0 | AT9: =IF(B9<>"",IF(AD9="X",10,IF(AD9="M",0,IF(ISNUMBER(AD9),AD9,0)))+IF(AE9="X",10,IF(AE9="M",0,IF(ISNUMBER(AE9),AE9,0)))+IF(AF9="X",10,IF(AF9="M",0,IF(ISNUMBER(AF9),AF9,0)))+IF(AG9="X",10,IF(AG9="M",0,IF(ISNUMBER(AG9),AG9,0)))+IF(AH9="X",10,IF(AH9="M",0,IF(ISNUMBER(AH9),AH9,0)))+IF(AI9="X",10,IF(AI9="M",0,IF(ISNUMBER(AI9),AI9,0))),"") -> 0 | AU9: =IF(B9<>"",IF(AJ9="X",10,IF(AJ9="M",0,IF(ISNUMBER(AJ9),AJ9,0)))+IF(AK9="X",10,IF(AK9="M",0,IF(ISNUMBER(AK9),AK9,0)))+IF(AL9="X",10,IF(AL9="M",0,IF(ISNUMBER(AL9),AL9,0)))+IF(AM9="X",10,IF(AM9="M",0,IF(ISNUMBER(AM9),AM9,0)))+IF(AN9="X",10,IF(AN9="M",0,IF(ISNUMBER(AN9),AN9,0)))+IF(AO9="X",10,IF(AO9="M",0,IF(ISNUMBER(AO9),AO9,0))),"") -> 0 | AV9: =IF(B9<>"",AP9+AQ9+AR9+AS9+AT9+AU9,"") -> 0 | AW9: =IF(B9<>"",IF(F9="X",1,0)+IF(G9="X",1,0)+IF(H9="X",1,0)+IF(I9="X",1,0)+IF(J9="X",1,0)+IF(K9="X",1,0)+IF(L9="X",1,0)+IF(M9="X",1,0)+IF(N9="X",1,0)+IF(O9="X",1,0)+IF(P9="X",1,0)+IF(Q9="X",1,0)+IF(R9="X",1,0)+IF(S9="X",1,0)+IF(T9="X",1,0)+IF(U9="X",1,0)+IF(V9="X",1,0)+IF(W9="X",1,0)+IF(X9="X",1,0)+IF(Y9="X",1,0)+IF(Z9="X",1,0)+IF(AA9="X",1,0)+IF(AB9="X",1,0)+IF(AC9="X",1,0)+IF(AD9="X",1,0)+IF(AE9="X",1,0)+IF(AF9="X",1,0)+IF(AG9="X",1,0)+IF(AH9="X",1,0)+IF(AI9="X",1,0)+IF(AJ9="X",1,0)+IF(AK9="X",1,0)+IF(AL9="X",1,0)+IF(AM9="X",1,0)+IF(AN9="X",1,0)+IF(AO9="X",1,0),"") -> 0 | AX9: =IF(B9<>"",IF(OR(F9="X",F9=10),1,0)+IF(OR(G9="X",G9=10),1,0)+IF(OR(H9="X",H9=10),1,0)+IF(OR(I9="X",I9=10),1,0)+IF(OR(J9="X",J9=10),1,0)+IF(OR(K9="X",K9=10),1,0)+IF(OR(L9="X",L9=10),1,0)+IF(OR(M9="X",M9=10),1,0)+IF(OR(N9="X",N9=10),1,0)+IF(OR(O9="X",O9=10),1,0)+IF(OR(P9="X",P9=10),1,0)+IF(OR(Q9="X",Q9=10),1,0)+IF(OR(R9="X",R9=10),1,0)+IF(OR(S9="X",S9=10),1,0)+IF(OR(T9="X",T9=10),1,0)+IF(OR(U9="X",U9=10),1,0)+IF(OR(V9="X",V9=10),1,0)+IF(OR(W9="X",W9=10),1,0)+IF(OR(X9="X",X9=10),1,0)+IF(OR(Y9="X",Y9=10),1,0)+IF(OR(Z9="X",Z9=10),1,0)+IF(OR(AA9="X",AA9=10),1,0)+IF(OR(AB9="X",AB9=10),1,0)+IF(OR(AC9="X",AC9=10),1,0)+IF(OR(AD9="X",AD9=10),1,0)+IF(OR(AE9="X",AE9=10),1,0)+IF(OR(AF9="X",AF9=10),1,0)+IF(OR(AG9="X",AG9=10),1,0)+IF(OR(AH9="X",AH9=10),1,0)+IF(OR(AI9="X",AI9=10),1,0)+IF(OR(AJ9="X",AJ9=10),1,0)+IF(OR(AK9="X",AK9=10),1,0)+IF(OR(AL9="X",AL9=10),1,0)+IF(OR(AM9="X",AM9=10),1,0)+IF(OR(AN9="X",AN9=10),1,0)+IF(OR(AO9="X",AO9=10),1,0),"") -> 0 | AY9: =IF(B9<>"",IF(F9=9,1,0)+IF(G9=9,1,0)+IF(H9=9,1,0)+IF(I9=9,1,0)+IF(J9=9,1,0)+IF(K9=9,1,0)+IF(L9=9,1,0)+IF(M9=9,1,0)+IF(N9=9,1,0)+IF(O9=9,1,0)+IF(P9=9,1,0)+IF(Q9=9,1,0)+IF(R9=9,1,0)+IF(S9=9,1,0)+IF(T9=9,1,0)+IF(U9=9,1,0)+IF(V9=9,1,0)+IF(W9=9,1,0)+IF(X9=9,1,0)+IF(Y9=9,1,0)+IF(Z9=9,1,0)+IF(AA9=9,1,0)+IF(AB9=9,1,0)+IF(AC9=9,1,0)+IF(AD9=9,1,0)+IF(AE9=9,1,0)+IF(AF9=9,1,0)+IF(AG9=9,1,0)+IF(AH9=9,1,0)+IF(AI9=9,1,0)+IF(AJ9=9,1,0)+IF(AK9=9,1,0)+IF(AL9=9,1,0)+IF(AM9=9,1,0)+IF(AN9=9,1,0)+IF(AO9=9,1,0),"") -> 0 | AZ9: =IF(B9<>"",SUMPRODUCT(($AV$6:$AV$1000>AV9)*ISNUMBER($AV$6:$AV$1000))+1+SUMPRODUCT(($AV$6:$AV$1000=AV9)*($AW$6:$AW$1000>AW9)*ISNUMBER($AV$6:$AV$1000)*ISNUMBER($AW$6:$AW$1000))+SUMPRODUCT(($AV$6:$AV$1000=AV9)*($AW$6:$AW$1000=AW9)*($AX$6:$AX$1000>AX9)*ISNUMBER($AV$6:$AV$1000)*ISNUMBER($AX$6:$AX$1000))+SUMPRODUCT(($AV$6:$AV$1000=AV9)*($AW$6:$AW$1000=AW9)*($AX$6:$AX$1000=AX9)*($AY$6:$AY$1000>AY9)*ISNUMBER($AV$6:$AV$1000)*ISNUMBER($AY$6:$AY$1000)),"") -> 1 | BB9: =IF(B9<>"",SUMPRODUCT(($AV$6:$AV$1000>AV9)*ISNUMBER($AV$6:$AV$1000))+1+SUMPRODUCT(($AV$6:$AV$1000=AV9)*($AW$6:$AW$1000>AW9)*ISNUMBER($AV$6:$AV$1000)*ISNUMBER($AW$6:$AW$1000))+SUMPRODUCT(($AV$6:$AV$1000=AV9)*($AW$6:$AW$1000=AW9)*($AX$6:$AX$1000>AX9)*ISNUMBER($AV$6:$AV$1000)*ISNUMBER($AX$6:$AX$1000))+SUMPRODUCT(($AV$6:$AV$1000=AV9)*($AW$6:$AW$1000=AW9)*($AX$6:$AX$1000=AX9)*($AY$6:$AY$1000>AY9)*ISNUMBER($AV$6:$AV$1000)*ISNUMBER($AY$6:$AY$1000))+SUMPRODUCT(($AV$6:$AV$1000=AV9)*($AW$6:$AW$1000=AW9)*($AX$6:$AX$1000=AX9)*($AY$6:$AY$1000=AY9)*($BA$6:$BA$1000>BA9)*ISNUMBER($AV$6:$AV$1000)*ISNUMBER($BA$6:$BA$1000)),"") -> 1
A10: =IF(B10<>"",COUNTA($B$6:B10),"") -> 5 | B10: Sheena Marie Monico | C10: Olympic Recurve | D10: Pasig AC | E10: =IF(B10="","",IF(COUNTA($B$6:$B$69)<=(E5-D5+1),(D5+MOD(A10-1,(E5-D5+1))),(D5+MOD(A10-1,(E5-D5+1)))&CHAR(65+FLOOR((A10-1)/(E5-D5+1),1)))) -> 3B | AP10: =IF(B10<>"",IF(F10="X",10,IF(F10="M",0,IF(ISNUMBER(F10),F10,0)))+IF(G10="X",10,IF(G10="M",0,IF(ISNUMBER(G10),G10,0)))+IF(H10="X",10,IF(H10="M",0,IF(ISNUMBER(H10),H10,0)))+IF(I10="X",10,IF(I10="M",0,IF(ISNUMBER(I10),I10,0)))+IF(J10="X",10,IF(J10="M",0,IF(ISNUMBER(J10),J10,0)))+IF(K10="X",10,IF(K10="M",0,IF(ISNUMBER(K10),K10,0))),"") -> 0 | AQ10: =IF(B10<>"",IF(L10="X",10,IF(L10="M",0,IF(ISNUMBER(L10),L10,0)))+IF(M10="X",10,IF(M10="M",0,IF(ISNUMBER(M10),M10,0)))+IF(N10="X",10,IF(N10="M",0,IF(ISNUMBER(N10),N10,0)))+IF(O10="X",10,IF(O10="M",0,IF(ISNUMBER(O10),O10,0)))+IF(P10="X",10,IF(P10="M",0,IF(ISNUMBER(P10),P10,0)))+IF(Q10="X",10,IF(Q10="M",0,IF(ISNUMBER(Q10),Q10,0))),"") -> 0 | AR10: =IF(B10<>"",IF(R10="X",10,IF(R10="M",0,IF(ISNUMBER(R10),R10,0)))+IF(S10="X",10,IF(S10="M",0,IF(ISNUMBER(S10),S10,0)))+IF(T10="X",10,IF(T10="M",0,IF(ISNUMBER(T10),T10,0)))+IF(U10="X",10,IF(U10="M",0,IF(ISNUMBER(U10),U10,0)))+IF(V10="X",10,IF(V10="M",0,IF(ISNUMBER(V10),V10,0)))+IF(W10="X",10,IF(W10="M",0,IF(ISNUMBER(W10),W10,0))),"") -> 0 | AS10: =IF(B10<>"",IF(X10="X",10,IF(X10="M",0,IF(ISNUMBER(X10),X10,0)))+IF(Y10="X",10,IF(Y10="M",0,IF(ISNUMBER(Y10),Y10,0)))+IF(Z10="X",10,IF(Z10="M",0,IF(ISNUMBER(Z10),Z10,0)))+IF(AA10="X",10,IF(AA10="M",0,IF(ISNUMBER(AA10),AA10,0)))+IF(AB10="X",10,IF(AB10="M",0,IF(ISNUMBER(AB10),AB10,0)))+IF(AC10="X",10,IF(AC10="M",0,IF(ISNUMBER(AC10),AC10,0))),"") -> 0 | AT10: =IF(B10<>"",IF(AD10="X",10,IF(AD10="M",0,IF(ISNUMBER(AD10),AD10,0)))+IF(AE10="X",10,IF(AE10="M",0,IF(ISNUMBER(AE10),AE10,0)))+IF(AF10="X",10,IF(AF10="M",0,IF(ISNUMBER(AF10),AF10,0)))+IF(AG10="X",10,IF(AG10="M",0,IF(ISNUMBER(AG10),AG10,0)))+IF(AH10="X",10,IF(AH10="M",0,IF(ISNUMBER(AH10),AH10,0)))+IF(AI10="X",10,IF(AI10="M",0,IF(ISNUMBER(AI10),AI10,0))),"") -> 0 | AU10: =IF(B10<>"",IF(AJ10="X",10,IF(AJ10="M",0,IF(ISNUMBER(AJ10),AJ10,0)))+IF(AK10="X",10,IF(AK10="M",0,IF(ISNUMBER(AK10),AK10,0)))+IF(AL10="X",10,IF(AL10="M",0,IF(ISNUMBER(AL10),AL10,0)))+IF(AM10="X",10,IF(AM10="M",0,IF(ISNUMBER(AM10),AM10,0)))+IF(AN10="X",10,IF(AN10="M",0,IF(ISNUMBER(AN10),AN10,0)))+IF(AO10="X",10,IF(AO10="M",0,IF(ISNUMBER(AO10),AO10,0))),"") -> 0 | AV10: =IF(B10<>"",AP10+AQ10+AR10+AS10+AT10+AU10,"") -> 0 | AW10: =IF(B10<>"",IF(F10="X",1,0)+IF(G10="X",1,0)+IF(H10="X",1,0)+IF(I10="X",1,0)+IF(J10="X",1,0)+IF(K10="X",1,0)+IF(L10="X",1,0)+IF(M10="X",1,0)+IF(N10="X",1,0)+IF(O10="X",1,0)+IF(P10="X",1,0)+IF(Q10="X",1,0)+IF(R10="X",1,0)+IF(S10="X",1,0)+IF(T10="X",1,0)+IF(U10="X",1,0)+IF(V10="X",1,0)+IF(W10="X",1,0)+IF(X10="X",1,0)+IF(Y10="X",1,0)+IF(Z10="X",1,0)+IF(AA10="X",1,0)+IF(AB10="X",1,0)+IF(AC10="X",1,0)+IF(AD10="X",1,0)+IF(AE10="X",1,0)+IF(AF10="X",1,0)+IF(AG10="X",1,0)+IF(AH10="X",1,0)+IF(AI10="X",1,0)+IF(AJ10="X",1,0)+IF(AK10="X",1,0)+IF(AL10="X",1,0)+IF(AM10="X",1,0)+IF(AN10="X",1,0)+IF(AO10="X",1,0),"") -> 0 | AX10: =IF(B10<>"",IF(OR(F10="X",F10=10),1,0)+IF(OR(G10="X",G10=10),1,0)+IF(OR(H10="X",H10=10),1,0)+IF(OR(I10="X",I10=10),1,0)+IF(OR(J10="X",J10=10),1,0)+IF(OR(K10="X",K10=10),1,0)+IF(OR(L10="X",L10=10),1,0)+IF(OR(M10="X",M10=10),1,0)+IF(OR(N10="X",N10=10),1,0)+IF(OR(O10="X",O10=10),1,0)+IF(OR(P10="X",P10=10),1,0)+IF(OR(Q10="X",Q10=10),1,0)+IF(OR(R10="X",R10=10),1,0)+IF(OR(S10="X",S10=10),1,0)+IF(OR(T10="X",T10=10),1,0)+IF(OR(U10="X",U10=10),1,0)+IF(OR(V10="X",V10=10),1,0)+IF(OR(W10="X",W10=10),1,0)+IF(OR(X10="X",X10=10),1,0)+IF(OR(Y10="X",Y10=10),1,0)+IF(OR(Z10="X",Z10=10),1,0)+IF(OR(AA10="X",AA10=10),1,0)+IF(OR(AB10="X",AB10=10),1,0)+IF(OR(AC10="X",AC10=10),1,0)+IF(OR(AD10="X",AD10=10),1,0)+IF(OR(AE10="X",AE10=10),1,0)+IF(OR(AF10="X",AF10=10),1,0)+IF(OR(AG10="X",AG10=10),1,0)+IF(OR(AH10="X",AH10=10),1,0)+IF(OR(AI10="X",AI10=10),1,0)+IF(OR(AJ10="X",AJ10=10),1,0)+IF(OR(AK10="X",AK10=10),1,0)+IF(OR(AL10="X",AL10=10),1,0)+IF(OR(AM10="X",AM10=10),1,0)+IF(OR(AN10="X",AN10=10),1,0)+IF(OR(AO10="X",AO10=10),1,0),"") -> 0 | AY10: =IF(B10<>"",IF(F10=9,1,0)+IF(G10=9,1,0)+IF(H10=9,1,0)+IF(I10=9,1,0)+IF(J10=9,1,0)+IF(K10=9,1,0)+IF(L10=9,1,0)+IF(M10=9,1,0)+IF(N10=9,1,0)+IF(O10=9,1,0)+IF(P10=9,1,0)+IF(Q10=9,1,0)+IF(R10=9,1,0)+IF(S10=9,1,0)+IF(T10=9,1,0)+IF(U10=9,1,0)+IF(V10=9,1,0)+IF(W10=9,1,0)+IF(X10=9,1,0)+IF(Y10=9,1,0)+IF(Z10=9,1,0)+IF(AA10=9,1,0)+IF(AB10=9,1,0)+IF(AC10=9,1,0)+IF(AD10=9,1,0)+IF(AE10=9,1,0)+IF(AF10=9,1,0)+IF(AG10=9,1,0)+IF(AH10=9,1,0)+IF(AI10=9,1,0)+IF(AJ10=9,1,0)+IF(AK10=9,1,0)+IF(AL10=9,1,0)+IF(AM10=9,1,0)+IF(AN10=9,1,0)+IF(AO10=9,1,0),"") -> 0 | AZ10: =IF(B10<>"",SUMPRODUCT(($AV$6:$AV$1000>AV10)*ISNUMBER($AV$6:$AV$1000))+1+SUMPRODUCT(($AV$6:$AV$1000=AV10)*($AW$6:$AW$1000>AW10)*ISNUMBER($AV$6:$AV$1000)*ISNUMBER($AW$6:$AW$1000))+SUMPRODUCT(($AV$6:$AV$1000=AV10)*($AW$6:$AW$1000=AW10)*($AX$6:$AX$1000>AX10)*ISNUMBER($AV$6:$AV$1000)*ISNUMBER($AX$6:$AX$1000))+SUMPRODUCT(($AV$6:$AV$1000=AV10)*($AW$6:$AW$1000=AW10)*($AX$6:$AX$1000=AX10)*($AY$6:$AY$1000>AY10)*ISNUMBER($AV$6:$AV$1000)*ISNUMBER($AY$6:$AY$1000)),"") -> 1 | BB10: =IF(B10<>"",SUMPRODUCT(($AV$6:$AV$1000>AV10)*ISNUMBER($AV$6:$AV$1000))+1+SUMPRODUCT(($AV$6:$AV$1000=AV10)*($AW$6:$AW$1000>AW10)*ISNUMBER($AV$6:$AV$1000)*ISNUMBER($AW$6:$AW$1000))+SUMPRODUCT(($AV$6:$AV$1000=AV10)*($AW$6:$AW$1000=AW10)*($AX$6:$AX$1000>AX10)*ISNUMBER($AV$6:$AV$1000)*ISNUMBER($AX$6:$AX$1000))+SUMPRODUCT(($AV$6:$AV$1000=AV10)*($AW$6:$AW$1000=AW10)*($AX$6:$AX$1000=AX10)*($AY$6:$AY$1000>AY10)*ISNUMBER($AV$6:$AV$1000)*ISNUMBER($AY$6:$AY$1000))+SUMPRODUCT(($AV$6:$AV$1000=AV10)*($AW$6:$AW$1000=AW10)*($AX$6:$AX$1000=AX10)*($AY$6:$AY$1000=AY10)*($BA$6:$BA$1000>BA10)*ISNUMBER($AV$6:$AV$1000)*ISNUMBER($BA$6:$BA$1000)),"") -> 1
A11: =IF(B11<>"",COUNTA($B$6:B11),"") -> 6 | B11: Stella Mae Magalang | C11: Olympic Recurve | D11: Buting | E11: =IF(B11="","",IF(COUNTA($B$6:$B$69)<=(E5-D5+1),(D5+MOD(A11-1,(E5-D5+1))),(D5+MOD(A11-1,(E5-D5+1)))&CHAR(65+FLOOR((A11-1)/(E5-D5+1),1)))) -> 4B | AP11: =IF(B11<>"",IF(F11="X",10,IF(F11="M",0,IF(ISNUMBER(F11),F11,0)))+IF(G11="X",10,IF(G11="M",0,IF(ISNUMBER(G11),G11,0)))+IF(H11="X",10,IF(H11="M",0,IF(ISNUMBER(H11),H11,0)))+IF(I11="X",10,IF(I11="M",0,IF(ISNUMBER(I11),I11,0)))+IF(J11="X",10,IF(J11="M",0,IF(ISNUMBER(J11),J11,0)))+IF(K11="X",10,IF(K11="M",0,IF(ISNUMBER(K11),K11,0))),"") -> 0 | AQ11: =IF(B11<>"",IF(L11="X",10,IF(L11="M",0,IF(ISNUMBER(L11),L11,0)))+IF(M11="X",10,IF(M11="M",0,IF(ISNUMBER(M11),M11,0)))+IF(N11="X",10,IF(N11="M",0,IF(ISNUMBER(N11),N11,0)))+IF(O11="X",10,IF(O11="M",0,IF(ISNUMBER(O11),O11,0)))+IF(P11="X",10,IF(P11="M",0,IF(ISNUMBER(P11),P11,0)))+IF(Q11="X",10,IF(Q11="M",0,IF(ISNUMBER(Q11),Q11,0))),"") -> 0 | AR11: =IF(B11<>"",IF(R11="X",10,IF(R11="M",0,IF(ISNUMBER(R11),R11,0)))+IF(S11="X",10,IF(S11="M",0,IF(ISNUMBER(S11),S11,0)))+IF(T11="X",10,IF(T11="M",0,IF(ISNUMBER(T11),T11,0)))+IF(U11="X",10,IF(U11="M",0,IF(ISNUMBER(U11),U11,0)))+IF(V11="X",10,IF(V11="M",0,IF(ISNUMBER(V11),V11,0)))+IF(W11="X",10,IF(W11="M",0,IF(ISNUMBER(W11),W11,0))),"") -> 0 | AS11: =IF(B11<>"",IF(X11="X",10,IF(X11="M",0,IF(ISNUMBER(X11),X11,0)))+IF(Y11="X",10,IF(Y11="M",0,IF(ISNUMBER(Y11),Y11,0)))+IF(Z11="X",10,IF(Z11="M",0,IF(ISNUMBER(Z11),Z11,0)))+IF(AA11="X",10,IF(AA11="M",0,IF(ISNUMBER(AA11),AA11,0)))+IF(AB11="X",10,IF(AB11="M",0,IF(ISNUMBER(AB11),AB11,0)))+IF(AC11="X",10,IF(AC11="M",0,IF(ISNUMBER(AC11),AC11,0))),"") -> 0 | AT11: =IF(B11<>"",IF(AD11="X",10,IF(AD11="M",0,IF(ISNUMBER(AD11),AD11,0)))+IF(AE11="X",10,IF(AE11="M",0,IF(ISNUMBER(AE11),AE11,0)))+IF(AF11="X",10,IF(AF11="M",0,IF(ISNUMBER(AF11),AF11,0)))+IF(AG11="X",10,IF(AG11="M",0,IF(ISNUMBER(AG11),AG11,0)))+IF(AH11="X",10,IF(AH11="M",0,IF(ISNUMBER(AH11),AH11,0)))+IF(AI11="X",10,IF(AI11="M",0,IF(ISNUMBER(AI11),AI11,0))),"") -> 0 | AU11: =IF(B11<>"",IF(AJ11="X",10,IF(AJ11="M",0,IF(ISNUMBER(AJ11),AJ11,0)))+IF(AK11="X",10,IF(AK11="M",0,IF(ISNUMBER(AK11),AK11,0)))+IF(AL11="X",10,IF(AL11="M",0,IF(ISNUMBER(AL11),AL11,0)))+IF(AM11="X",10,IF(AM11="M",0,IF(ISNUMBER(AM11),AM11,0)))+IF(AN11="X",10,IF(AN11="M",0,IF(ISNUMBER(AN11),AN11,0)))+IF(AO11="X",10,IF(AO11="M",0,IF(ISNUMBER(AO11),AO11,0))),"") -> 0 | AV11: =IF(B11<>"",AP11+AQ11+AR11+AS11+AT11+AU11,"") -> 0 | AW11: =IF(B11<>"",IF(F11="X",1,0)+IF(G11="X",1,0)+IF(H11="X",1,0)+IF(I11="X",1,0)+IF(J11="X",1,0)+IF(K11="X",1,0)+IF(L11="X",1,0)+IF(M11="X",1,0)+IF(N11="X",1,0)+IF(O11="X",1,0)+IF(P11="X",1,0)+IF(Q11="X",1,0)+IF(R11="X",1,0)+IF(S11="X",1,0)+IF(T11="X",1,0)+IF(U11="X",1,0)+IF(V11="X",1,0)+IF(W11="X",1,0)+IF(X11="X",1,0)+IF(Y11="X",1,0)+IF(Z11="X",1,0)+IF(AA11="X",1,0)+IF(AB11="X",1,0)+IF(AC11="X",1,0)+IF(AD11="X",1,0)+IF(AE11="X",1,0)+IF(AF11="X",1,0)+IF(AG11="X",1,0)+IF(AH11="X",1,0)+IF(AI11="X",1,0)+IF(AJ11="X",1,0)+IF(AK11="X",1,0)+IF(AL11="X",1,0)+IF(AM11="X",1,0)+IF(AN11="X",1,0)+IF(AO11="X",1,0),"") -> 0 | AX11: =IF(B11<>"",IF(OR(F11="X",F11=10),1,0)+IF(OR(G11="X",G11=10),1,0)+IF(OR(H11="X",H11=10),1,0)+IF(OR(I11="X",I11=10),1,0)+IF(OR(J11="X",J11=10),1,0)+IF(OR(K11="X",K11=10),1,0)+IF(OR(L11="X",L11=10),1,0)+IF(OR(M11="X",M11=10),1,0)+IF(OR(N11="X",N11=10),1,0)+IF(OR(O11="X",O11=10),1,0)+IF(OR(P11="X",P11=10),1,0)+IF(OR(Q11="X",Q11=10),1,0)+IF(OR(R11="X",R11=10),1,0)+IF(OR(S11="X",S11=10),1,0)+IF(OR(T11="X",T11=10),1,0)+IF(OR(U11="X",U11=10),1,0)+IF(OR(V11="X",V11=10),1,0)+IF(OR(W11="X",W11=10),1,0)+IF(OR(X11="X",X11=10),1,0)+IF(OR(Y11="X",Y11=10),1,0)+IF(OR(Z11="X",Z11=10),1,0)+IF(OR(AA11="X",AA11=10),1,0)+IF(OR(AB11="X",AB11=10),1,0)+IF(OR(AC11="X",AC11=10),1,0)+IF(OR(AD11="X",AD11=10),1,0)+IF(OR(AE11="X",AE11=10),1,0)+IF(OR(AF11="X",AF11=10),1,0)+IF(OR(AG11="X",AG11=10),1,0)+IF(OR(AH11="X",AH11=10),1,0)+IF(OR(AI11="X",AI11=10),1,0)+IF(OR(AJ11="X",AJ11=10),1,0)+IF(OR(AK11="X",AK11=10),1,0)+IF(OR(AL11="X",AL11=10),1,0)+IF(OR(AM11="X",AM11=10),1,0)+IF(OR(AN11="X",AN11=10),1,0)+IF(OR(AO11="X",AO11=10),1,0),"") -> 0 | AY11: =IF(B11<>"",IF(F11=9,1,0)+IF(G11=9,1,0)+IF(H11=9,1,0)+IF(I11=9,1,0)+IF(J11=9,1,0)+IF(K11=9,1,0)+IF(L11=9,1,0)+IF(M11=9,1,0)+IF(N11=9,1,0)+IF(O11=9,1,0)+IF(P11=9,1,0)+IF(Q11=9,1,0)+IF(R11=9,1,0)+IF(S11=9,1,0)+IF(T11=9,1,0)+IF(U11=9,1,0)+IF(V11=9,1,0)+IF(W11=9,1,0)+IF(X11=9,1,0)+IF(Y11=9,1,0)+IF(Z11=9,1,0)+IF(AA11=9,1,0)+IF(AB11=9,1,0)+IF(AC11=9,1,0)+IF(AD11=9,1,0)+IF(AE11=9,1,0)+IF(AF11=9,1,0)+IF(AG11=9,1,0)+IF(AH11=9,1,0)+IF(AI11=9,1,0)+IF(AJ11=9,1,0)+IF(AK11=9,1,0)+IF(AL11=9,1,0)+IF(AM11=9,1,0)+IF(AN11=9,1,0)+IF(AO11=9,1,0),"") -> 0 | AZ11: =IF(B11<>"",SUMPRODUCT(($AV$6:$AV$1000>AV11)*ISNUMBER($AV$6:$AV$1000))+1+SUMPRODUCT(($AV$6:$AV$1000=AV11)*($AW$6:$AW$1000>AW11)*ISNUMBER($AV$6:$AV$1000)*ISNUMBER($AW$6:$AW$1000))+SUMPRODUCT(($AV$6:$AV$1000=AV11)*($AW$6:$AW$1000=AW11)*($AX$6:$AX$1000>AX11)*ISNUMBER($AV$6:$AV$1000)*ISNUMBER($AX$6:$AX$1000))+SUMPRODUCT(($AV$6:$AV$1000=AV11)*($AW$6:$AW$1000=AW11)*($AX$6:$AX$1000=AX11)*($AY$6:$AY$1000>AY11)*ISNUMBER($AV$6:$AV$1000)*ISNUMBER($AY$6:$AY$1000)),"") -> 1 | BB11: =IF(B11<>"",SUMPRODUCT(($AV$6:$AV$1000>AV11)*ISNUMBER($AV$6:$AV$1000))+1+SUMPRODUCT(($AV$6:$AV$1000=AV11)*($AW$6:$AW$1000>AW11)*ISNUMBER($AV$6:$AV$1000)*ISNUMBER($AW$6:$AW$1000))+SUMPRODUCT(($AV$6:$AV$1000=AV11)*($AW$6:$AW$1000=AW11)*($AX$6:$AX$1000>AX11)*ISNUMBER($AV$6:$AV$1000)*ISNUMBER($AX$6:$AX$1000))+SUMPRODUCT(($AV$6:$AV$1000=AV11)*($AW$6:$AW$1000=AW11)*($AX$6:$AX$1000=AX11)*($AY$6:$AY$1000>AY11)*ISNUMBER($AV$6:$AV$1000)*ISNUMBER($AY$6:$AY$1000))+SUMPRODUCT(($AV$6:$AV$1000=AV11)*($AW$6:$AW$1000=AW11)*($AX$6:$AX$1000=AX11)*($AY$6:$AY$1000=AY11)*($BA$6:$BA$1000>BA11)*ISNUMBER($AV$6:$AV$1000)*ISNUMBER($BA$6:$BA$1000)),"") -> 1
A12: =IF(B12<>"",COUNTA($B$6:B12),"") -> 7 | B12: Aizen Zainna Quiellan M. Riego | C12: Olympic Recurve | D12: PAC Maybunga | E12: =IF(B12="","",IF(COUNTA($B$6:$B$69)<=(E5-D5+1),(D5+MOD(A12-1,(E5-D5+1))),(D5+MOD(A12-1,(E5-D5+1)))&CHAR(65+FLOOR((A12-1)/(E5-D5+1),1)))) -> 5B | AP12: =IF(B12<>"",IF(F12="X",10,IF(F12="M",0,IF(ISNUMBER(F12),F12,0)))+IF(G12="X",10,IF(G12="M",0,IF(ISNUMBER(G12),G12,0)))+IF(H12="X",10,IF(H12="M",0,IF(ISNUMBER(H12),H12,0)))+IF(I12="X",10,IF(I12="M",0,IF(ISNUMBER(I12),I12,0)))+IF(J12="X",10,IF(J12="M",0,IF(ISNUMBER(J12),J12,0)))+IF(K12="X",10,IF(K12="M",0,IF(ISNUMBER(K12),K12,0))),"") -> 0 | AQ12: =IF(B12<>"",IF(L12="X",10,IF(L12="M",0,IF(ISNUMBER(L12),L12,0)))+IF(M12="X",10,IF(M12="M",0,IF(ISNUMBER(M12),M12,0)))+IF(N12="X",10,IF(N12="M",0,IF(ISNUMBER(N12),N12,0)))+IF(O12="X",10,IF(O12="M",0,IF(ISNUMBER(O12),O12,0)))+IF(P12="X",10,IF(P12="M",0,IF(ISNUMBER(P12),P12,0)))+IF(Q12="X",10,IF(Q12="M",0,IF(ISNUMBER(Q12),Q12,0))),"") -> 0 | AR12: =IF(B12<>"",IF(R12="X",10,IF(R12="M",0,IF(ISNUMBER(R12),R12,0)))+IF(S12="X",10,IF(S12="M",0,IF(ISNUMBER(S12),S12,0)))+IF(T12="X",10,IF(T12="M",0,IF(ISNUMBER(T12),T12,0)))+IF(U12="X",10,IF(U12="M",0,IF(ISNUMBER(U12),U12,0)))+IF(V12="X",10,IF(V12="M",0,IF(ISNUMBER(V12),V12,0)))+IF(W12="X",10,IF(W12="M",0,IF(ISNUMBER(W12),W12,0))),"") -> 0 | AS12: =IF(B12<>"",IF(X12="X",10,IF(X12="M",0,IF(ISNUMBER(X12),X12,0)))+IF(Y12="X",10,IF(Y12="M",0,IF(ISNUMBER(Y12),Y12,0)))+IF(Z12="X",10,IF(Z12="M",0,IF(ISNUMBER(Z12),Z12,0)))+IF(AA12="X",10,IF(AA12="M",0,IF(ISNUMBER(AA12),AA12,0)))+IF(AB12="X",10,IF(AB12="M",0,IF(ISNUMBER(AB12),AB12,0)))+IF(AC12="X",10,IF(AC12="M",0,IF(ISNUMBER(AC12),AC12,0))),"") -> 0 | AT12: =IF(B12<>"",IF(AD12="X",10,IF(AD12="M",0,IF(ISNUMBER(AD12),AD12,0)))+IF(AE12="X",10,IF(AE12="M",0,IF(ISNUMBER(AE12),AE12,0)))+IF(AF12="X",10,IF(AF12="M",0,IF(ISNUMBER(AF12),AF12,0)))+IF(AG12="X",10,IF(AG12="M",0,IF(ISNUMBER(AG12),AG12,0)))+IF(AH12="X",10,IF(AH12="M",0,IF(ISNUMBER(AH12),AH12,0)))+IF(AI12="X",10,IF(AI12="M",0,IF(ISNUMBER(AI12),AI12,0))),"") -> 0 | AU12: =IF(B12<>"",IF(AJ12="X",10,IF(AJ12="M",0,IF(ISNUMBER(AJ12),AJ12,0)))+IF(AK12="X",10,IF(AK12="M",0,IF(ISNUMBER(AK12),AK12,0)))+IF(AL12="X",10,IF(AL12="M",0,IF(ISNUMBER(AL12),AL12,0)))+IF(AM12="X",10,IF(AM12="M",0,IF(ISNUMBER(AM12),AM12,0)))+IF(AN12="X",10,IF(AN12="M",0,IF(ISNUMBER(AN12),AN12,0)))+IF(AO12="X",10,IF(AO12="M",0,IF(ISNUMBER(AO12),AO12,0))),"") -> 0 | AV12: =IF(B12<>"",AP12+AQ12+AR12+AS12+AT12+AU12,"") -> 0 | AW12: =IF(B12<>"",IF(F12="X",1,0)+IF(G12="X",1,0)+IF(H12="X",1,0)+IF(I12="X",1,0)+IF(J12="X",1,0)+IF(K12="X",1,0)+IF(L12="X",1,0)+IF(M12="X",1,0)+IF(N12="X",1,0)+IF(O12="X",1,0)+IF(P12="X",1,0)+IF(Q12="X",1,0)+IF(R12="X",1,0)+IF(S12="X",1,0)+IF(T12="X",1,0)+IF(U12="X",1,0)+IF(V12="X",1,0)+IF(W12="X",1,0)+IF(X12="X",1,0)+IF(Y12="X",1,0)+IF(Z12="X",1,0)+IF(AA12="X",1,0)+IF(AB12="X",1,0)+IF(AC12="X",1,0)+IF(AD12="X",1,0)+IF(AE12="X",1,0)+IF(AF12="X",1,0)+IF(AG12="X",1,0)+IF(AH12="X",1,0)+IF(AI12="X",1,0)+IF(AJ12="X",1,0)+IF(AK12="X",1,0)+IF(AL12="X",1,0)+IF(AM12="X",1,0)+IF(AN12="X",1,0)+IF(AO12="X",1,0),"") -> 0 | AX12: =IF(B12<>"",IF(OR(F12="X",F12=10),1,0)+IF(OR(G12="X",G12=10),1,0)+IF(OR(H12="X",H12=10),1,0)+IF(OR(I12="X",I12=10),1,0)+IF(OR(J12="X",J12=10),1,0)+IF(OR(K12="X",K12=10),1,0)+IF(OR(L12="X",L12=10),1,0)+IF(OR(M12="X",M12=10),1,0)+IF(OR(N12="X",N12=10),1,0)+IF(OR(O12="X",O12=10),1,0)+IF(OR(P12="X",P12=10),1,0)+IF(OR(Q12="X",Q12=10),1,0)+IF(OR(R12="X",R12=10),1,0)+IF(OR(S12="X",S12=10),1,0)+IF(OR(T12="X",T12=10),1,0)+IF(OR(U12="X",U12=10),1,0)+IF(OR(V12="X",V12=10),1,0)+IF(OR(W12="X",W12=10),1,0)+IF(OR(X12="X",X12=10),1,0)+IF(OR(Y12="X",Y12=10),1,0)+IF(OR(Z12="X",Z12=10),1,0)+IF(OR(AA12="X",AA12=10),1,0)+IF(OR(AB12="X",AB12=10),1,0)+IF(OR(AC12="X",AC12=10),1,0)+IF(OR(AD12="X",AD12=10),1,0)+IF(OR(AE12="X",AE12=10),1,0)+IF(OR(AF12="X",AF12=10),1,0)+IF(OR(AG12="X",AG12=10),1,0)+IF(OR(AH12="X",AH12=10),1,0)+IF(OR(AI12="X",AI12=10),1,0)+IF(OR(AJ12="X",AJ12=10),1,0)+IF(OR(AK12="X",AK12=10),1,0)+IF(OR(AL12="X",AL12=10),1,0)+IF(OR(AM12="X",AM12=10),1,0)+IF(OR(AN12="X",AN12=10),1,0)+IF(OR(AO12="X",AO12=10),1,0),"") -> 0 | AY12: =IF(B12<>"",IF(F12=9,1,0)+IF(G12=9,1,0)+IF(H12=9,1,0)+IF(I12=9,1,0)+IF(J12=9,1,0)+IF(K12=9,1,0)+IF(L12=9,1,0)+IF(M12=9,1,0)+IF(N12=9,1,0)+IF(O12=9,1,0)+IF(P12=9,1,0)+IF(Q12=9,1,0)+IF(R12=9,1,0)+IF(S12=9,1,0)+IF(T12=9,1,0)+IF(U12=9,1,0)+IF(V12=9,1,0)+IF(W12=9,1,0)+IF(X12=9,1,0)+IF(Y12=9,1,0)+IF(Z12=9,1,0)+IF(AA12=9,1,0)+IF(AB12=9,1,0)+IF(AC12=9,1,0)+IF(AD12=9,1,0)+IF(AE12=9,1,0)+IF(AF12=9,1,0)+IF(AG12=9,1,0)+IF(AH12=9,1,0)+IF(AI12=9,1,0)+IF(AJ12=9,1,0)+IF(AK12=9,1,0)+IF(AL12=9,1,0)+IF(AM12=9,1,0)+IF(AN12=9,1,0)+IF(AO12=9,1,0),"") -> 0 | AZ12: =IF(B12<>"",SUMPRODUCT(($AV$6:$AV$1000>AV12)*ISNUMBER($AV$6:$AV$1000))+1+SUMPRODUCT(($AV$6:$AV$1000=AV12)*($AW$6:$AW$1000>AW12)*ISNUMBER($AV$6:$AV$1000)*ISNUMBER($AW$6:$AW$1000))+SUMPRODUCT(($AV$6:$AV$1000=AV12)*($AW$6:$AW$1000=AW12)*($AX$6:$AX$1000>AX12)*ISNUMBER($AV$6:$AV$1000)*ISNUMBER($AX$6:$AX$1000))+SUMPRODUCT(($AV$6:$AV$1000=AV12)*($AW$6:$AW$1000=AW12)*($AX$6:$AX$1000=AX12)*($AY$6:$AY$1000>AY12)*ISNUMBER($AV$6:$AV$1000)*ISNUMBER($AY$6:$AY$1000)),"") -> 1 | BB12: =IF(B12<>"",SUMPRODUCT(($AV$6:$AV$1000>AV12)*ISNUMBER($AV$6:$AV$1000))+1+SUMPRODUCT(($AV$6:$AV$1000=AV12)*($AW$6:$AW$1000>AW12)*ISNUMBER($AV$6:$AV$1000)*ISNUMBER($AW$6:$AW$1000))+SUMPRODUCT(($AV$6:$AV$1000=AV12)*($AW$6:$AW$1000=AW12)*($AX$6:$AX$1000>AX12)*ISNUMBER($AV$6:$AV$1000)*ISNUMBER($AX$6:$AX$1000))+SUMPRODUCT(($AV$6:$AV$1000=AV12)*($AW$6:$AW$1000=AW12)*($AX$6:$AX$1000=AX12)*($AY$6:$AY$1000>AY12)*ISNUMBER($AV$6:$AV$1000)*ISNUMBER($AY$6:$AY$1000))+SUMPRODUCT(($AV$6:$AV$1000=AV12)*($AW$6:$AW$1000=AW12)*($AX$6:$AX$1000=AX12)*($AY$6:$AY$1000=AY12)*($BA$6:$BA$1000>BA12)*ISNUMBER($AV$6:$AV$1000)*ISNUMBER($BA$6:$BA$1000)),"") -> 1
A13: =IF(B13<>"",COUNTA($B$6:B13),"") -> 8 | B13: Leira Maxene Lagrimas | C13: Olympic Recurve | D13: Brgy. Sta Lucia | E13: =IF(B13="","",IF(COUNTA($B$6:$B$69)<=(E5-D5+1),(D5+MOD(A13-1,(E5-D5+1))),(D5+MOD(A13-1,(E5-D5+1)))&CHAR(65+FLOOR((A13-1)/(E5-D5+1),1)))) -> 6B | AP13: =IF(B13<>"",IF(F13="X",10,IF(F13="M",0,IF(ISNUMBER(F13),F13,0)))+IF(G13="X",10,IF(G13="M",0,IF(ISNUMBER(G13),G13,0)))+IF(H13="X",10,IF(H13="M",0,IF(ISNUMBER(H13),H13,0)))+IF(I13="X",10,IF(I13="M",0,IF(ISNUMBER(I13),I13,0)))+IF(J13="X",10,IF(J13="M",0,IF(ISNUMBER(J13),J13,0)))+IF(K13="X",10,IF(K13="M",0,IF(ISNUMBER(K13),K13,0))),"") -> 0 | AQ13: =IF(B13<>"",IF(L13="X",10,IF(L13="M",0,IF(ISNUMBER(L13),L13,0)))+IF(M13="X",10,IF(M13="M",0,IF(ISNUMBER(M13),M13,0)))+IF(N13="X",10,IF(N13="M",0,IF(ISNUMBER(N13),N13,0)))+IF(O13="X",10,IF(O13="M",0,IF(ISNUMBER(O13),O13,0)))+IF(P13="X",10,IF(P13="M",0,IF(ISNUMBER(P13),P13,0)))+IF(Q13="X",10,IF(Q13="M",0,IF(ISNUMBER(Q13),Q13,0))),"") -> 0 | AR13: =IF(B13<>"",IF(R13="X",10,IF(R13="M",0,IF(ISNUMBER(R13),R13,0)))+IF(S13="X",10,IF(S13="M",0,IF(ISNUMBER(S13),S13,0)))+IF(T13="X",10,IF(T13="M",0,IF(ISNUMBER(T13),T13,0)))+IF(U13="X",10,IF(U13="M",0,IF(ISNUMBER(U13),U13,0)))+IF(V13="X",10,IF(V13="M",0,IF(ISNUMBER(V13),V13,0)))+IF(W13="X",10,IF(W13="M",0,IF(ISNUMBER(W13),W13,0))),"") -> 0 | AS13: =IF(B13<>"",IF(X13="X",10,IF(X13="M",0,IF(ISNUMBER(X13),X13,0)))+IF(Y13="X",10,IF(Y13="M",0,IF(ISNUMBER(Y13),Y13,0)))+IF(Z13="X",10,IF(Z13="M",0,IF(ISNUMBER(Z13),Z13,0)))+IF(AA13="X",10,IF(AA13="M",0,IF(ISNUMBER(AA13),AA13,0)))+IF(AB13="X",10,IF(AB13="M",0,IF(ISNUMBER(AB13),AB13,0)))+IF(AC13="X",10,IF(AC13="M",0,IF(ISNUMBER(AC13),AC13,0))),"") -> 0 | AT13: =IF(B13<>"",IF(AD13="X",10,IF(AD13="M",0,IF(ISNUMBER(AD13),AD13,0)))+IF(AE13="X",10,IF(AE13="M",0,IF(ISNUMBER(AE13),AE13,0)))+IF(AF13="X",10,IF(AF13="M",0,IF(ISNUMBER(AF13),AF13,0)))+IF(AG13="X",10,IF(AG13="M",0,IF(ISNUMBER(AG13),AG13,0)))+IF(AH13="X",10,IF(AH13="M",0,IF(ISNUMBER(AH13),AH13,0)))+IF(AI13="X",10,IF(AI13="M",0,IF(ISNUMBER(AI13),AI13,0))),"") -> 0 | AU13: =IF(B13<>"",IF(AJ13="X",10,IF(AJ13="M",0,IF(ISNUMBER(AJ13),AJ13,0)))+IF(AK13="X",10,IF(AK13="M",0,IF(ISNUMBER(AK13),AK13,0)))+IF(AL13="X",10,IF(AL13="M",0,IF(ISNUMBER(AL13),AL13,0)))+IF(AM13="X",10,IF(AM13="M",0,IF(ISNUMBER(AM13),AM13,0)))+IF(AN13="X",10,IF(AN13="M",0,IF(ISNUMBER(AN13),AN13,0)))+IF(AO13="X",10,IF(AO13="M",0,IF(ISNUMBER(AO13),AO13,0))),"") -> 0 | AV13: =IF(B13<>"",AP13+AQ13+AR13+AS13+AT13+AU13,"") -> 0 | AW13: =IF(B13<>"",IF(F13="X",1,0)+IF(G13="X",1,0)+IF(H13="X",1,0)+IF(I13="X",1,0)+IF(J13="X",1,0)+IF(K13="X",1,0)+IF(L13="X",1,0)+IF(M13="X",1,0)+IF(N13="X",1,0)+IF(O13="X",1,0)+IF(P13="X",1,0)+IF(Q13="X",1,0)+IF(R13="X",1,0)+IF(S13="X",1,0)+IF(T13="X",1,0)+IF(U13="X",1,0)+IF(V13="X",1,0)+IF(W13="X",1,0)+IF(X13="X",1,0)+IF(Y13="X",1,0)+IF(Z13="X",1,0)+IF(AA13="X",1,0)+IF(AB13="X",1,0)+IF(AC13="X",1,0)+IF(AD13="X",1,0)+IF(AE13="X",1,0)+IF(AF13="X",1,0)+IF(AG13="X",1,0)+IF(AH13="X",1,0)+IF(AI13="X",1,0)+IF(AJ13="X",1,0)+IF(AK13="X",1,0)+IF(AL13="X",1,0)+IF(AM13="X",1,0)+IF(AN13="X",1,0)+IF(AO13="X",1,0),"") -> 0 | AX13: =IF(B13<>"",IF(OR(F13="X",F13=10),1,0)+IF(OR(G13="X",G13=10),1,0)+IF(OR(H13="X",H13=10),1,0)+IF(OR(I13="X",I13=10),1,0)+IF(OR(J13="X",J13=10),1,0)+IF(OR(K13="X",K13=10),1,0)+IF(OR(L13="X",L13=10),1,0)+IF(OR(M13="X",M13=10),1,0)+IF(OR(N13="X",N13=10),1,0)+IF(OR(O13="X",O13=10),1,0)+IF(OR(P13="X",P13=10),1,0)+IF(OR(Q13="X",Q13=10),1,0)+IF(OR(R13="X",R13=10),1,0)+IF(OR(S13="X",S13=10),1,0)+IF(OR(T13="X",T13=10),1,0)+IF(OR(U13="X",U13=10),1,0)+IF(OR(V13="X",V13=10),1,0)+IF(OR(W13="X",W13=10),1,0)+IF(OR(X13="X",X13=10),1,0)+IF(OR(Y13="X",Y13=10),1,0)+IF(OR(Z13="X",Z13=10),1,0)+IF(OR(AA13="X",AA13=10),1,0)+IF(OR(AB13="X",AB13=10),1,0)+IF(OR(AC13="X",AC13=10),1,0)+IF(OR(AD13="X",AD13=10),1,0)+IF(OR(AE13="X",AE13=10),1,0)+IF(OR(AF13="X",AF13=10),1,0)+IF(OR(AG13="X",AG13=10),1,0)+IF(OR(AH13="X",AH13=10),1,0)+IF(OR(AI13="X",AI13=10),1,0)+IF(OR(AJ13="X",AJ13=10),1,0)+IF(OR(AK13="X",AK13=10),1,0)+IF(OR(AL13="X",AL13=10),1,0)+IF(OR(AM13="X",AM13=10),1,0)+IF(OR(AN13="X",AN13=10),1,0)+IF(OR(AO13="X",AO13=10),1,0),"") -> 0 | AY13: =IF(B13<>"",IF(F13=9,1,0)+IF(G13=9,1,0)+IF(H13=9,1,0)+IF(I13=9,1,0)+IF(J13=9,1,0)+IF(K13=9,1,0)+IF(L13=9,1,0)+IF(M13=9,1,0)+IF(N13=9,1,0)+IF(O13=9,1,0)+IF(P13=9,1,0)+IF(Q13=9,1,0)+IF(R13=9,1,0)+IF(S13=9,1,0)+IF(T13=9,1,0)+IF(U13=9,1,0)+IF(V13=9,1,0)+IF(W13=9,1,0)+IF(X13=9,1,0)+IF(Y13=9,1,0)+IF(Z13=9,1,0)+IF(AA13=9,1,0)+IF(AB13=9,1,0)+IF(AC13=9,1,0)+IF(AD13=9,1,0)+IF(AE13=9,1,0)+IF(AF13=9,1,0)+IF(AG13=9,1,0)+IF(AH13=9,1,0)+IF(AI13=9,1,0)+IF(AJ13=9,1,0)+IF(AK13=9,1,0)+IF(AL13=9,1,0)+IF(AM13=9,1,0)+IF(AN13=9,1,0)+IF(AO13=9,1,0),"") -> 0 | AZ13: =IF(B13<>"",SUMPRODUCT(($AV$6:$AV$1000>AV13)*ISNUMBER($AV$6:$AV$1000))+1+SUMPRODUCT(($AV$6:$AV$1000=AV13)*($AW$6:$AW$1000>AW13)*ISNUMBER($AV$6:$AV$1000)*ISNUMBER($AW$6:$AW$1000))+SUMPRODUCT(($AV$6:$AV$1000=AV13)*($AW$6:$AW$1000=AW13)*($AX$6:$AX$1000>AX13)*ISNUMBER($AV$6:$AV$1000)*ISNUMBER($AX$6:$AX$1000))+SUMPRODUCT(($AV$6:$AV$1000=AV13)*($AW$6:$AW$1000=AW13)*($AX$6:$AX$1000=AX13)*($AY$6:$AY$1000>AY13)*ISNUMBER($AV$6:$AV$1000)*ISNUMBER($AY$6:$AY$1000)),"") -> 1 | BB13: =IF(B13<>"",SUMPRODUCT(($AV$6:$AV$1000>AV13)*ISNUMBER($AV$6:$AV$1000))+1+SUMPRODUCT(($AV$6:$AV$1000=AV13)*($AW$6:$AW$1000>AW13)*ISNUMBER($AV$6:$AV$1000)*ISNUMBER($AW$6:$AW$1000))+SUMPRODUCT(($AV$6:$AV$1000=AV13)*($AW$6:$AW$1000=AW13)*($AX$6:$AX$1000>AX13)*ISNUMBER($AV$6:$AV$1000)*ISNUMBER($AX$6:$AX$1000))+SUMPRODUCT(($AV$6:$AV$1000=AV13)*($AW$6:$AW$1000=AW13)*($AX$6:$AX$1000=AX13)*($AY$6:$AY$1000>AY13)*ISNUMBER($AV$6:$AV$1000)*ISNUMBER($AY$6:$AY$1000))+SUMPRODUCT(($AV$6:$AV$1000=AV13)*($AW$6:$AW$1000=AW13)*($AX$6:$AX$1000=AX13)*($AY$6:$AY$1000=AY13)*($BA$6:$BA$1000>BA13)*ISNUMBER($AV$6:$AV$1000)*ISNUMBER($BA$6:$BA$1000)),"") -> 1
A14: =IF(B14<>"",COUNTA($B$6:B14),"") -> 9 | B14: Jasmine Eizelle P. Dipad | C14: Olympic Recurve | D14: N/A | E14: =IF(B14="","",IF(COUNTA($B$6:$B$69)<=(E5-D5+1),(D5+MOD(A14-1,(E5-D5+1))),(D5+MOD(A14-1,(E5-D5+1)))&CHAR(65+FLOOR((A14-1)/(E5-D5+1),1)))) -> 3C | AP14: =IF(B14<>"",IF(F14="X",10,IF(F14="M",0,IF(ISNUMBER(F14),F14,0)))+IF(G14="X",10,IF(G14="M",0,IF(ISNUMBER(G14),G14,0)))+IF(H14="X",10,IF(H14="M",0,IF(ISNUMBER(H14),H14,0)))+IF(I14="X",10,IF(I14="M",0,IF(ISNUMBER(I14),I14,0)))+IF(J14="X",10,IF(J14="M",0,IF(ISNUMBER(J14),J14,0)))+IF(K14="X",10,IF(K14="M",0,IF(ISNUMBER(K14),K14,0))),"") -> 0 | AQ14: =IF(B14<>"",IF(L14="X",10,IF(L14="M",0,IF(ISNUMBER(L14),L14,0)))+IF(M14="X",10,IF(M14="M",0,IF(ISNUMBER(M14),M14,0)))+IF(N14="X",10,IF(N14="M",0,IF(ISNUMBER(N14),N14,0)))+IF(O14="X",10,IF(O14="M",0,IF(ISNUMBER(O14),O14,0)))+IF(P14="X",10,IF(P14="M",0,IF(ISNUMBER(P14),P14,0)))+IF(Q14="X",10,IF(Q14="M",0,IF(ISNUMBER(Q14),Q14,0))),"") -> 0 | AR14: =IF(B14<>"",IF(R14="X",10,IF(R14="M",0,IF(ISNUMBER(R14),R14,0)))+IF(S14="X",10,IF(S14="M",0,IF(ISNUMBER(S14),S14,0)))+IF(T14="X",10,IF(T14="M",0,IF(ISNUMBER(T14),T14,0)))+IF(U14="X",10,IF(U14="M",0,IF(ISNUMBER(U14),U14,0)))+IF(V14="X",10,IF(V14="M",0,IF(ISNUMBER(V14),V14,0)))+IF(W14="X",10,IF(W14="M",0,IF(ISNUMBER(W14),W14,0))),"") -> 0 | AS14: =IF(B14<>"",IF(X14="X",10,IF(X14="M",0,IF(ISNUMBER(X14),X14,0)))+IF(Y14="X",10,IF(Y14="M",0,IF(ISNUMBER(Y14),Y14,0)))+IF(Z14="X",10,IF(Z14="M",0,IF(ISNUMBER(Z14),Z14,0)))+IF(AA14="X",10,IF(AA14="M",0,IF(ISNUMBER(AA14),AA14,0)))+IF(AB14="X",10,IF(AB14="M",0,IF(ISNUMBER(AB14),AB14,0)))+IF(AC14="X",10,IF(AC14="M",0,IF(ISNUMBER(AC14),AC14,0))),"") -> 0 | AT14: =IF(B14<>"",IF(AD14="X",10,IF(AD14="M",0,IF(ISNUMBER(AD14),AD14,0)))+IF(AE14="X",10,IF(AE14="M",0,IF(ISNUMBER(AE14),AE14,0)))+IF(AF14="X",10,IF(AF14="M",0,IF(ISNUMBER(AF14),AF14,0)))+IF(AG14="X",10,IF(AG14="M",0,IF(ISNUMBER(AG14),AG14,0)))+IF(AH14="X",10,IF(AH14="M",0,IF(ISNUMBER(AH14),AH14,0)))+IF(AI14="X",10,IF(AI14="M",0,IF(ISNUMBER(AI14),AI14,0))),"") -> 0 | AU14: =IF(B14<>"",IF(AJ14="X",10,IF(AJ14="M",0,IF(ISNUMBER(AJ14),AJ14,0)))+IF(AK14="X",10,IF(AK14="M",0,IF(ISNUMBER(AK14),AK14,0)))+IF(AL14="X",10,IF(AL14="M",0,IF(ISNUMBER(AL14),AL14,0)))+IF(AM14="X",10,IF(AM14="M",0,IF(ISNUMBER(AM14),AM14,0)))+IF(AN14="X",10,IF(AN14="M",0,IF(ISNUMBER(AN14),AN14,0)))+IF(AO14="X",10,IF(AO14="M",0,IF(ISNUMBER(AO14),AO14,0))),"") -> 0 | AV14: =IF(B14<>"",AP14+AQ14+AR14+AS14+AT14+AU14,"") -> 0 | AW14: =IF(B14<>"",IF(F14="X",1,0)+IF(G14="X",1,0)+IF(H14="X",1,0)+IF(I14="X",1,0)+IF(J14="X",1,0)+IF(K14="X",1,0)+IF(L14="X",1,0)+IF(M14="X",1,0)+IF(N14="X",1,0)+IF(O14="X",1,0)+IF(P14="X",1,0)+IF(Q14="X",1,0)+IF(R14="X",1,0)+IF(S14="X",1,0)+IF(T14="X",1,0)+IF(U14="X",1,0)+IF(V14="X",1,0)+IF(W14="X",1,0)+IF(X14="X",1,0)+IF(Y14="X",1,0)+IF(Z14="X",1,0)+IF(AA14="X",1,0)+IF(AB14="X",1,0)+IF(AC14="X",1,0)+IF(AD14="X",1,0)+IF(AE14="X",1,0)+IF(AF14="X",1,0)+IF(AG14="X",1,0)+IF(AH14="X",1,0)+IF(AI14="X",1,0)+IF(AJ14="X",1,0)+IF(AK14="X",1,0)+IF(AL14="X",1,0)+IF(AM14="X",1,0)+IF(AN14="X",1,0)+IF(AO14="X",1,0),"") -> 0 | AX14: =IF(B14<>"",IF(OR(F14="X",F14=10),1,0)+IF(OR(G14="X",G14=10),1,0)+IF(OR(H14="X",H14=10),1,0)+IF(OR(I14="X",I14=10),1,0)+IF(OR(J14="X",J14=10),1,0)+IF(OR(K14="X",K14=10),1,0)+IF(OR(L14="X",L14=10),1,0)+IF(OR(M14="X",M14=10),1,0)+IF(OR(N14="X",N14=10),1,0)+IF(OR(O14="X",O14=10),1,0)+IF(OR(P14="X",P14=10),1,0)+IF(OR(Q14="X",Q14=10),1,0)+IF(OR(R14="X",R14=10),1,0)+IF(OR(S14="X",S14=10),1,0)+IF(OR(T14="X",T14=10),1,0)+IF(OR(U14="X",U14=10),1,0)+IF(OR(V14="X",V14=10),1,0)+IF(OR(W14="X",W14=10),1,0)+IF(OR(X14="X",X14=10),1,0)+IF(OR(Y14="X",Y14=10),1,0)+IF(OR(Z14="X",Z14=10),1,0)+IF(OR(AA14="X",AA14=10),1,0)+IF(OR(AB14="X",AB14=10),1,0)+IF(OR(AC14="X",AC14=10),1,0)+IF(OR(AD14="X",AD14=10),1,0)+IF(OR(AE14="X",AE14=10),1,0)+IF(OR(AF14="X",AF14=10),1,0)+IF(OR(AG14="X",AG14=10),1,0)+IF(OR(AH14="X",AH14=10),1,0)+IF(OR(AI14="X",AI14=10),1,0)+IF(OR(AJ14="X",AJ14=10),1,0)+IF(OR(AK14="X",AK14=10),1,0)+IF(OR(AL14="X",AL14=10),1,0)+IF(OR(AM14="X",AM14=10),1,0)+IF(OR(AN14="X",AN14=10),1,0)+IF(OR(AO14="X",AO14=10),1,0),"") -> 0 | AY14: =IF(B14<>"",IF(F14=9,1,0)+IF(G14=9,1,0)+IF(H14=9,1,0)+IF(I14=9,1,0)+IF(J14=9,1,0)+IF(K14=9,1,0)+IF(L14=9,1,0)+IF(M14=9,1,0)+IF(N14=9,1,0)+IF(O14=9,1,0)+IF(P14=9,1,0)+IF(Q14=9,1,0)+IF(R14=9,1,0)+IF(S14=9,1,0)+IF(T14=9,1,0)+IF(U14=9,1,0)+IF(V14=9,1,0)+IF(W14=9,1,0)+IF(X14=9,1,0)+IF(Y14=9,1,0)+IF(Z14=9,1,0)+IF(AA14=9,1,0)+IF(AB14=9,1,0)+IF(AC14=9,1,0)+IF(AD14=9,1,0)+IF(AE14=9,1,0)+IF(AF14=9,1,0)+IF(AG14=9,1,0)+IF(AH14=9,1,0)+IF(AI14=9,1,0)+IF(AJ14=9,1,0)+IF(AK14=9,1,0)+IF(AL14=9,1,0)+IF(AM14=9,1,0)+IF(AN14=9,1,0)+IF(AO14=9,1,0),"") -> 0 | AZ14: =IF(B14<>"",SUMPRODUCT(($AV$6:$AV$1000>AV14)*ISNUMBER($AV$6:$AV$1000))+1+SUMPRODUCT(($AV$6:$AV$1000=AV14)*($AW$6:$AW$1000>AW14)*ISNUMBER($AV$6:$AV$1000)*ISNUMBER($AW$6:$AW$1000))+SUMPRODUCT(($AV$6:$AV$1000=AV14)*($AW$6:$AW$1000=AW14)*($AX$6:$AX$1000>AX14)*ISNUMBER($AV$6:$AV$1000)*ISNUMBER($AX$6:$AX$1000))+SUMPRODUCT(($AV$6:$AV$1000=AV14)*($AW$6:$AW$1000=AW14)*($AX$6:$AX$1000=AX14)*($AY$6:$AY$1000>AY14)*ISNUMBER($AV$6:$AV$1000)*ISNUMBER($AY$6:$AY$1000)),"") -> 1 | BB14: =IF(B14<>"",SUMPRODUCT(($AV$6:$AV$1000>AV14)*ISNUMBER($AV$6:$AV$1000))+1+SUMPRODUCT(($AV$6:$AV$1000=AV14)*($AW$6:$AW$1000>AW14)*ISNUMBER($AV$6:$AV$1000)*ISNUMBER($AW$6:$AW$1000))+SUMPRODUCT(($AV$6:$AV$1000=AV14)*($AW$6:$AW$1000=AW14)*($AX$6:$AX$1000>AX14)*ISNUMBER($AV$6:$AV$1000)*ISNUMBER($AX$6:$AX$1000))+SUMPRODUCT(($AV$6:$AV$1000=AV14)*($AW$6:$AW$1000=AW14)*($AX$6:$AX$1000=AX14)*($AY$6:$AY$1000>AY14)*ISNUMBER($AV$6:$AV$1000)*ISNUMBER($AY$6:$AY$1000))+SUMPRODUCT(($AV$6:$AV$1000=AV14)*($AW$6:$AW$1000=AW14)*($AX$6:$AX$1000=AX14)*($AY$6:$AY$1000=AY14)*($BA$6:$BA$1000>BA14)*ISNUMBER($AV$6:$AV$1000)*ISNUMBER($BA$6:$BA$1000)),"") -> 1
